Workbook

Sheet Urban
A1: 0 | B1: CREDIT REALLOCATION | M1: LEAVE | AD1: LEAVE | AG1: LEAVE | AH1: LEAVE
A2: S/N | B2: Customer | C2: Area | D2: GBNL URN | E2: Initial Credit Value | F2: To be Utilized | G2: Balance | H2: New Credit Value | I2: Name | J2: Region | K2: AREA | L2: GBNL URN | M2: August '22 Target Value (₦) | N2: Current Target | O2: B & H Switch | P2: Rothmans Switch | Q2: Benson & Hedges Boost | R2: Benson & Hedges Demi-Slims | S2: Benson & Hedges Flavour | T2: Dunhill Switch | U2: ST Moritz By Dunhill | V2: Rothmans Menthol | W2: Pall Mall Filter | X2: Pall Mall Menthol | Y2: Rothmans Flavour | Z2: Royal Std Filter | AA2: Pall Mall - Excel Blend | AB2: Pall Mall Boost | AC2: New August Target Value | AD2: August '22 Initial Credit Deployment (₦) | AE2: August '22 Initial Credit Deployment (₦) BD View | AF2: BD Check | AG2: Extra Credit Request (₦) | AH2: Total Credit for Upload August '22 (₦) | AI2: % Credit Exposure vs Initial Target | AJ2: % Credit Exposure vs New expected volume | AK2: Justification
A3: 1 | I3: Alh. Idiat Olatunji - 2 | J3: SWR | K3: Agege | L3: LAC3712 | M3: =IFERROR(VLOOKUP($L3,[1]Consolidated!$C$9:$AC$341,27,0),0) -> 17643000 | N3: =IFERROR(VLOOKUP($L3,[1]Consolidated!$C$9:$AC$341,5,0),0) -> 80 | O3: 0 | X3: 0 | AC3: =(VLOOKUP($O$2,Prices!$E$3:$F$17,2,FALSE)*Urban!O3)+(VLOOKUP($P$2,Prices!$E$3:$F$17,2,FALSE)*Urban!P3)+(VLOOKUP($Q$2,Prices!$E$3:$F$17,2,FALSE)*Urban!Q3)+(VLOOKUP($R$2,Prices!$E$3:$F$17,2,FALSE)*Urban!R3)+(VLOOKUP($S$2,Prices!$E$3:$F$17,2,FALSE)*Urban!S3)+(VLOOKUP($T$2,Prices!$E$3:$F$17,2,FALSE)*Urban!T3)+(VLOOKUP($U$2,Prices!$E$3:$F$17,2,FALSE)*Urban!U3)+(VLOOKUP($V$2,Prices!$E$3:$F$17,2,FALSE)*Urban!V3)+(VLOOKUP($W$2,Prices!$E$3:$F$17,2,FALSE)*Urban!W3)+(VLOOKUP($X$2,Prices!$E$3:$F$17,2,FALSE)*Urban!X3)+(VLOOKUP($Y$2,Prices!$E$3:$F$17,2,FALSE)*Urban!Y3)+(VLOOKUP($Z$2,Prices!$E$3:$F$17,2,FALSE)*Urban!Z3)+(VLOOKUP($AA$2,Prices!$E$3:$F$17,2,FALSE)*Urban!AA3)+(VLOOKUP($AB$2,Prices!$E$3:$F$17,2,FALSE)*Urban!AB3)+M3 -> 17643000 | AD3: 6172650 | AF3: =AD3-AE3 -> 6172650 | AG3: 0 | AH3: =AD3+AG3 -> 6172650 | AI3: =AH3/M3 -> 0.34986397 | AJ3: =AH3/AC3 -> 0.34986397
A4: 2 | I4: Iya Tosin | J4: SWR | K4: Agege | L4: LAC2292 | M4: =IFERROR(VLOOKUP($L4,[1]Consolidated!$C$9:$AC$341,27,0),0) -> 19740000 | N4: =IFERROR(VLOOKUP($L4,[1]Consolidated!$C$9:$AC$341,5,0),0) -> 90 | AC4: =(VLOOKUP($O$2,Prices!$E$3:$F$17,2,FALSE)*Urban!O4)+(VLOOKUP($P$2,Prices!$E$3:$F$17,2,FALSE)*Urban!P4)+(VLOOKUP($Q$2,Prices!$E$3:$F$17,2,FALSE)*Urban!Q4)+(VLOOKUP($R$2,Prices!$E$3:$F$17,2,FALSE)*Urban!R4)+(VLOOKUP($S$2,Prices!$E$3:$F$17,2,FALSE)*Urban!S4)+(VLOOKUP($T$2,Prices!$E$3:$F$17,2,FALSE)*Urban!T4)+(VLOOKUP($U$2,Prices!$E$3:$F$17,2,FALSE)*Urban!U4)+(VLOOKUP($V$2,Prices!$E$3:$F$17,2,FALSE)*Urban!V4)+(VLOOKUP($W$2,Prices!$E$3:$F$17,2,FALSE)*Urban!W4)+(VLOOKUP($X$2,Prices!$E$3:$F$17,2,FALSE)*Urban!X4)+(VLOOKUP($Y$2,Prices!$E$3:$F$17,2,FALSE)*Urban!Y4)+(VLOOKUP($Z$2,Prices!$E$3:$F$17,2,FALSE)*Urban!Z4)+(VLOOKUP($AA$2,Prices!$E$3:$F$17,2,FALSE)*Urban!AA4)+(VLOOKUP($AB$2,Prices!$E$3:$F$17,2,FALSE)*Urban!AB4)+M4 -> 19740000 | AD4: 6908670 | AF4: =AD4-AE4 -> 6908670 | AH4: =AD4+AG4 -> 6908670 | AI4: =AH4/M4 -> 0.34998328 | AJ4: =AH4/AC4 -> 0.34998328
A5: 3 | I5: Iya Mohammed | J5: SWR | K5: Agege | L5: LAC0666 | M5: =IFERROR(VLOOKUP($L5,[1]Consolidated!$C$9:$AC$341,27,0),0) -> 18900000 | N5: =IFERROR(VLOOKUP($L5,[1]Consolidated!$C$9:$AC$341,5,0),0) -> 80 | AC5: =(VLOOKUP($O$2,Prices!$E$3:$F$17,2,FALSE)*Urban!O5)+(VLOOKUP($P$2,Prices!$E$3:$F$17,2,FALSE)*Urban!P5)+(VLOOKUP($Q$2,Prices!$E$3:$F$17,2,FALSE)*Urban!Q5)+(VLOOKUP($R$2,Prices!$E$3:$F$17,2,FALSE)*Urban!R5)+(VLOOKUP($S$2,Prices!$E$3:$F$17,2,FALSE)*Urban!S5)+(VLOOKUP($T$2,Prices!$E$3:$F$17,2,FALSE)*Urban!T5)+(VLOOKUP($U$2,Prices!$E$3:$F$17,2,FALSE)*Urban!U5)+(VLOOKUP($V$2,Prices!$E$3:$F$17,2,FALSE)*Urban!V5)+(VLOOKUP($W$2,Prices!$E$3:$F$17,2,FALSE)*Urban!W5)+(VLOOKUP($X$2,Prices!$E$3:$F$17,2,FALSE)*Urban!X5)+(VLOOKUP($Y$2,Prices!$E$3:$F$17,2,FALSE)*Urban!Y5)+(VLOOKUP($Z$2,Prices!$E$3:$F$17,2,FALSE)*Urban!Z5)+(VLOOKUP($AA$2,Prices!$E$3:$F$17,2,FALSE)*Urban!AA5)+(VLOOKUP($AB$2,Prices!$E$3:$F$17,2,FALSE)*Urban!AB5)+M5 -> 18900000 | AD5: 6613740 | AF5: =AD5-AE5 -> 6613740 | AH5: =AD5+AG5 -> 6613740 | AI5: =AH5/M5 -> 0.34993333 | AJ5: =AH5/AC5 -> 0.34993333
A6: 4 | I6: IYABO | J6: SWR | K6: Agege | L6: CTAK0007 | M6: =IFERROR(VLOOKUP($L6,[1]Consolidated!$C$9:$AC$341,27,0),0) -> 20470000 | N6: =IFERROR(VLOOKUP($L6,[1]Consolidated!$C$9:$AC$341,5,0),0) -> 90 | O6: 10 | AC6: =(VLOOKUP($O$2,Prices!$E$3:$F$17,2,FALSE)*Urban!O6)+(VLOOKUP($P$2,Prices!$E$3:$F$17,2,FALSE)*Urban!P6)+(VLOOKUP($Q$2,Prices!$E$3:$F$17,2,FALSE)*Urban!Q6)+(VLOOKUP($R$2,Prices!$E$3:$F$17,2,FALSE)*Urban!R6)+(VLOOKUP($S$2,Prices!$E$3:$F$17,2,FALSE)*Urban!S6)+(VLOOKUP($T$2,Prices!$E$3:$F$17,2,FALSE)*Urban!T6)+(VLOOKUP($U$2,Prices!$E$3:$F$17,2,FALSE)*Urban!U6)+(VLOOKUP($V$2,Prices!$E$3:$F$17,2,FALSE)*Urban!V6)+(VLOOKUP($W$2,Prices!$E$3:$F$17,2,FALSE)*Urban!W6)+(VLOOKUP($X$2,Prices!$E$3:$F$17,2,FALSE)*Urban!X6)+(VLOOKUP($Y$2,Prices!$E$3:$F$17,2,FALSE)*Urban!Y6)+(VLOOKUP($Z$2,Prices!$E$3:$F$17,2,FALSE)*Urban!Z6)+(VLOOKUP($AA$2,Prices!$E$3:$F$17,2,FALSE)*Urban!AA6)+(VLOOKUP($AB$2,Prices!$E$3:$F$17,2,FALSE)*Urban!AB6)+M6 -> 23080000 | AD6: 7073100 | AF6: =AD6-AE6 -> 7073100 | AG6: 9000000 | AH6: =AD6+AG6 -> 16073100 | AI6: =AH6/M6 -> 0.78520274 | AJ6: =AH6/AC6 -> 0.69640815 | AK6: She has cleared her July credit. Teller is attached
A7: 5 | I7: NDIGWE SAMUEL TOCHUKWU | J7: SWR | K7: Agege | L7: LAC2393 | M7: =IFERROR(VLOOKUP($L7,[1]Consolidated!$C$9:$AC$341,27,0),0) -> 19740000 | N7: =IFERROR(VLOOKUP($L7,[1]Consolidated!$C$9:$AC$341,5,0),0) -> 90 | AC7: =(VLOOKUP($O$2,Prices!$E$3:$F$17,2,FALSE)*Urban!O7)+(VLOOKUP($P$2,Prices!$E$3:$F$17,2,FALSE)*Urban!P7)+(VLOOKUP($Q$2,Prices!$E$3:$F$17,2,FALSE)*Urban!Q7)+(VLOOKUP($R$2,Prices!$E$3:$F$17,2,FALSE)*Urban!R7)+(VLOOKUP($S$2,Prices!$E$3:$F$17,2,FALSE)*Urban!S7)+(VLOOKUP($T$2,Prices!$E$3:$F$17,2,FALSE)*Urban!T7)+(VLOOKUP($U$2,Prices!$E$3:$F$17,2,FALSE)*Urban!U7)+(VLOOKUP($V$2,Prices!$E$3:$F$17,2,FALSE)*Urban!V7)+(VLOOKUP($W$2,Prices!$E$3:$F$17,2,FALSE)*Urban!W7)+(VLOOKUP($X$2,Prices!$E$3:$F$17,2,FALSE)*Urban!X7)+(VLOOKUP($Y$2,Prices!$E$3:$F$17,2,FALSE)*Urban!Y7)+(VLOOKUP($Z$2,Prices!$E$3:$F$17,2,FALSE)*Urban!Z7)+(VLOOKUP($AA$2,Prices!$E$3:$F$17,2,FALSE)*Urban!AA7)+(VLOOKUP($AB$2,Prices!$E$3:$F$17,2,FALSE)*Urban!AB7)+M7 -> 19740000 | AD7: 6908670 | AF7: =AD7-AE7 -> 6908670 | AH7: =AD7+AG7 -> 6908670 | AI7: =AH7/M7 -> 0.34998328 | AJ7: =AH7/AC7 -> 0.34998328
A8: 6 | I8: UGWU JONAS EMEKA | J8: SWR | K8: Agege | L8: LAC2392 | M8: =IFERROR(VLOOKUP($L8,[1]Consolidated!$C$9:$AC$341,27,0),0) -> 0 | N8: =IFERROR(VLOOKUP($L8,[1]Consolidated!$C$9:$AC$341,5,0),0) -> 0 | AC8: =(VLOOKUP($O$2,Prices!$E$3:$F$17,2,FALSE)*Urban!O8)+(VLOOKUP($P$2,Prices!$E$3:$F$17,2,FALSE)*Urban!P8)+(VLOOKUP($Q$2,Prices!$E$3:$F$17,2,FALSE)*Urban!Q8)+(VLOOKUP($R$2,Prices!$E$3:$F$17,2,FALSE)*Urban!R8)+(VLOOKUP($S$2,Prices!$E$3:$F$17,2,FALSE)*Urban!S8)+(VLOOKUP($T$2,Prices!$E$3:$F$17,2,FALSE)*Urban!T8)+(VLOOKUP($U$2,Prices!$E$3:$F$17,2,FALSE)*Urban!U8)+(VLOOKUP($V$2,Prices!$E$3:$F$17,2,FALSE)*Urban!V8)+(VLOOKUP($W$2,Prices!$E$3:$F$17,2,FALSE)*Urban!W8)+(VLOOKUP($X$2,Prices!$E$3:$F$17,2,FALSE)*Urban!X8)+(VLOOKUP($Y$2,Prices!$E$3:$F$17,2,FALSE)*Urban!Y8)+(VLOOKUP($Z$2,Prices!$E$3:$F$17,2,FALSE)*Urban!Z8)+(VLOOKUP($AA$2,Prices!$E$3:$F$17,2,FALSE)*Urban!AA8)+(VLOOKUP($AB$2,Prices!$E$3:$F$17,2,FALSE)*Urban!AB8)+M8 -> 0 | AD8: 0 | AF8: =AD8-AE8 -> 0 | AH8: =AD8+AG8 -> 0 | AI8: =AH8/M8 -> #DIV/0! | AJ8: =AH8/AC8 -> #DIV/0!
A9: 7 | I9: BABA SODIQ | J9: SWR | K9: Agege | L9: LAC0073 | M9: =IFERROR(VLOOKUP($L9,[1]Consolidated!$C$9:$AC$341,27,0),0) -> 0 | N9: =IFERROR(VLOOKUP($L9,[1]Consolidated!$C$9:$AC$341,5,0),0) -> 0 | AC9: =(VLOOKUP($O$2,Prices!$E$3:$F$17,2,FALSE)*Urban!O9)+(VLOOKUP($P$2,Prices!$E$3:$F$17,2,FALSE)*Urban!P9)+(VLOOKUP($Q$2,Prices!$E$3:$F$17,2,FALSE)*Urban!Q9)+(VLOOKUP($R$2,Prices!$E$3:$F$17,2,FALSE)*Urban!R9)+(VLOOKUP($S$2,Prices!$E$3:$F$17,2,FALSE)*Urban!S9)+(VLOOKUP($T$2,Prices!$E$3:$F$17,2,FALSE)*Urban!T9)+(VLOOKUP($U$2,Prices!$E$3:$F$17,2,FALSE)*Urban!U9)+(VLOOKUP($V$2,Prices!$E$3:$F$17,2,FALSE)*Urban!V9)+(VLOOKUP($W$2,Prices!$E$3:$F$17,2,FALSE)*Urban!W9)+(VLOOKUP($X$2,Prices!$E$3:$F$17,2,FALSE)*Urban!X9)+(VLOOKUP($Y$2,Prices!$E$3:$F$17,2,FALSE)*Urban!Y9)+(VLOOKUP($Z$2,Prices!$E$3:$F$17,2,FALSE)*Urban!Z9)+(VLOOKUP($AA$2,Prices!$E$3:$F$17,2,FALSE)*Urban!AA9)+(VLOOKUP($AB$2,Prices!$E$3:$F$17,2,FALSE)*Urban!AB9)+M9 -> 0 | AD9: 0 | AF9: =AD9-AE9 -> 0 | AH9: =AD9+AG9 -> 0 | AI9: =AH9/M9 -> #DIV/0! | AJ9: =AH9/AC9 -> #DIV/0!
A10: 8 | I10: ADEJOKE TIJANI | J10: SWR | K10: Agege | L10: CTAJ0007 | M10: =IFERROR(VLOOKUP($L10,[1]Consolidated!$C$9:$AC$341,27,0),0) -> 28200000 | N10: =IFERROR(VLOOKUP($L10,[1]Consolidated!$C$9:$AC$341,5,0),0) -> 120 | AC10: =(VLOOKUP($O$2,Prices!$E$3:$F$17,2,FALSE)*Urban!O10)+(VLOOKUP($P$2,Prices!$E$3:$F$17,2,FALSE)*Urban!P10)+(VLOOKUP($Q$2,Prices!$E$3:$F$17,2,FALSE)*Urban!Q10)+(VLOOKUP($R$2,Prices!$E$3:$F$17,2,FALSE)*Urban!R10)+(VLOOKUP($S$2,Prices!$E$3:$F$17,2,FALSE)*Urban!S10)+(VLOOKUP($T$2,Prices!$E$3:$F$17,2,FALSE)*Urban!T10)+(VLOOKUP($U$2,Prices!$E$3:$F$17,2,FALSE)*Urban!U10)+(VLOOKUP($V$2,Prices!$E$3:$F$17,2,FALSE)*Urban!V10)+(VLOOKUP($W$2,Prices!$E$3:$F$17,2,FALSE)*Urban!W10)+(VLOOKUP($X$2,Prices!$E$3:$F$17,2,FALSE)*Urban!X10)+(VLOOKUP($Y$2,Prices!$E$3:$F$17,2,FALSE)*Urban!Y10)+(VLOOKUP($Z$2,Prices!$E$3:$F$17,2,FALSE)*Urban!Z10)+(VLOOKUP($AA$2,Prices!$E$3:$F$17,2,FALSE)*Urban!AA10)+(VLOOKUP($AB$2,Prices!$E$3:$F$17,2,FALSE)*Urban!AB10)+M10 -> 28200000 | AD10: 9868410 | AF10: =AD10-AE10 -> 9868410 | AH10: =AD10+AG10 -> 9868410 | AI10: =AH10/M10 -> 0.34994362 | AJ10: =AH10/AC10 -> 0.34994362
A11: 9 | I11: MAMMAH ROSEMARY | J11: SWR | K11: Agege | L11: CTAJ0003 | M11: =IFERROR(VLOOKUP($L11,[1]Consolidated!$C$9:$AC$341,27,0),0) -> 17860000 | N11: =IFERROR(VLOOKUP($L11,[1]Consolidated!$C$9:$AC$341,5,0),0) -> 80 | AC11: =(VLOOKUP($O$2,Prices!$E$3:$F$17,2,FALSE)*Urban!O11)+(VLOOKUP($P$2,Prices!$E$3:$F$17,2,FALSE)*Urban!P11)+(VLOOKUP($Q$2,Prices!$E$3:$F$17,2,FALSE)*Urban!Q11)+(VLOOKUP($R$2,Prices!$E$3:$F$17,2,FALSE)*Urban!R11)+(VLOOKUP($S$2,Prices!$E$3:$F$17,2,FALSE)*Urban!S11)+(VLOOKUP($T$2,Prices!$E$3:$F$17,2,FALSE)*Urban!T11)+(VLOOKUP($U$2,Prices!$E$3:$F$17,2,FALSE)*Urban!U11)+(VLOOKUP($V$2,Prices!$E$3:$F$17,2,FALSE)*Urban!V11)+(VLOOKUP($W$2,Prices!$E$3:$F$17,2,FALSE)*Urban!W11)+(VLOOKUP($X$2,Prices!$E$3:$F$17,2,FALSE)*Urban!X11)+(VLOOKUP($Y$2,Prices!$E$3:$F$17,2,FALSE)*Urban!Y11)+(VLOOKUP($Z$2,Prices!$E$3:$F$17,2,FALSE)*Urban!Z11)+(VLOOKUP($AA$2,Prices!$E$3:$F$17,2,FALSE)*Urban!AA11)+(VLOOKUP($AB$2,Prices!$E$3:$F$17,2,FALSE)*Urban!AB11)+M11 -> 17860000 | AD11: 6237900 | AF11: =AD11-AE11 -> 6237900 | AH11: =AD11+AG11 -> 6237900 | AI11: =AH11/M11 -> 0.34926652 | AJ11: =AH11/AC11 -> 0.34926652
A12: 10 | I12: WONUJUWONLO VENTURE | J12: SWR | K12: Agege | L12: LAC2298 | M12: =IFERROR(VLOOKUP($L12,'[2]Top WH -National'!$D$9:$AC$124,26,0),0) -> 73428000 | N12: =IFERROR(VLOOKUP($L12,'[2]Top WH -National'!$D$9:$AC$124,4,0),0) -> 352 | AC12: =(VLOOKUP($O$2,Prices!$E$3:$F$17,2,FALSE)*Urban!O12)+(VLOOKUP($P$2,Prices!$E$3:$F$17,2,FALSE)*Urban!P12)+(VLOOKUP($Q$2,Prices!$E$3:$F$17,2,FALSE)*Urban!Q12)+(VLOOKUP($R$2,Prices!$E$3:$F$17,2,FALSE)*Urban!R12)+(VLOOKUP($S$2,Prices!$E$3:$F$17,2,FALSE)*Urban!S12)+(VLOOKUP($T$2,Prices!$E$3:$F$17,2,FALSE)*Urban!T12)+(VLOOKUP($U$2,Prices!$E$3:$F$17,2,FALSE)*Urban!U12)+(VLOOKUP($V$2,Prices!$E$3:$F$17,2,FALSE)*Urban!V12)+(VLOOKUP($W$2,Prices!$E$3:$F$17,2,FALSE)*Urban!W12)+(VLOOKUP($X$2,Prices!$E$3:$F$17,2,FALSE)*Urban!X12)+(VLOOKUP($Y$2,Prices!$E$3:$F$17,2,FALSE)*Urban!Y12)+(VLOOKUP($Z$2,Prices!$E$3:$F$17,2,FALSE)*Urban!Z12)+(VLOOKUP($AA$2,Prices!$E$3:$F$17,2,FALSE)*Urban!AA12)+(VLOOKUP($AB$2,Prices!$E$3:$F$17,2,FALSE)*Urban!AB12)+M12 -> 73428000 | AD12: 47840000 | AF12: =AD12-AE12 -> 47840000 | AH12: =AD12+AG12 -> 47840000 | AI12: =AH12/M12 -> 0.65152258 | AJ12: =AH12/AC12 -> 0.65152258
A13: 11 | I13: Iya Faidat Trading Stores | J13: SWR | K13: Agege | L13: LAC1605 | M13: =IFERROR(VLOOKUP($L13,[1]Consolidated!$C$9:$AC$341,27,0),0) -> 23290000 | N13: =IFERROR(VLOOKUP($L13,[1]Consolidated!$C$9:$AC$341,5,0),0) -> 100 | AC13: =(VLOOKUP($O$2,Prices!$E$3:$F$17,2,FALSE)*Urban!O13)+(VLOOKUP($P$2,Prices!$E$3:$F$17,2,FALSE)*Urban!P13)+(VLOOKUP($Q$2,Prices!$E$3:$F$17,2,FALSE)*Urban!Q13)+(VLOOKUP($R$2,Prices!$E$3:$F$17,2,FALSE)*Urban!R13)+(VLOOKUP($S$2,Prices!$E$3:$F$17,2,FALSE)*Urban!S13)+(VLOOKUP($T$2,Prices!$E$3:$F$17,2,FALSE)*Urban!T13)+(VLOOKUP($U$2,Prices!$E$3:$F$17,2,FALSE)*Urban!U13)+(VLOOKUP($V$2,Prices!$E$3:$F$17,2,FALSE)*Urban!V13)+(VLOOKUP($W$2,Prices!$E$3:$F$17,2,FALSE)*Urban!W13)+(VLOOKUP($X$2,Prices!$E$3:$F$17,2,FALSE)*Urban!X13)+(VLOOKUP($Y$2,Prices!$E$3:$F$17,2,FALSE)*Urban!Y13)+(VLOOKUP($Z$2,Prices!$E$3:$F$17,2,FALSE)*Urban!Z13)+(VLOOKUP($AA$2,Prices!$E$3:$F$17,2,FALSE)*Urban!AA13)+(VLOOKUP($AB$2,Prices!$E$3:$F$17,2,FALSE)*Urban!AB13)+M13 -> 23290000 | AD13: 8143200 | AF13: =AD13-AE13 -> 8143200 | AH13: =AD13+AG13 -> 8143200 | AI13: =AH13/M13 -> 0.34964362 | AJ13: =AH13/AC13 -> 0.34964362
A14: 12 | I14: Esther Jimoh | J14: SWR | K14: Agege | L14: LAC0281 | M14: =IFERROR(VLOOKUP($L14,[1]Consolidated!$C$9:$AC$341,27,0),0) -> 28200000 | N14: =IFERROR(VLOOKUP($L14,[1]Consolidated!$C$9:$AC$341,5,0),0) -> 120 | AC14: =(VLOOKUP($O$2,Prices!$E$3:$F$17,2,FALSE)*Urban!O14)+(VLOOKUP($P$2,Prices!$E$3:$F$17,2,FALSE)*Urban!P14)+(VLOOKUP($Q$2,Prices!$E$3:$F$17,2,FALSE)*Urban!Q14)+(VLOOKUP($R$2,Prices!$E$3:$F$17,2,FALSE)*Urban!R14)+(VLOOKUP($S$2,Prices!$E$3:$F$17,2,FALSE)*Urban!S14)+(VLOOKUP($T$2,Prices!$E$3:$F$17,2,FALSE)*Urban!T14)+(VLOOKUP($U$2,Prices!$E$3:$F$17,2,FALSE)*Urban!U14)+(VLOOKUP($V$2,Prices!$E$3:$F$17,2,FALSE)*Urban!V14)+(VLOOKUP($W$2,Prices!$E$3:$F$17,2,FALSE)*Urban!W14)+(VLOOKUP($X$2,Prices!$E$3:$F$17,2,FALSE)*Urban!X14)+(VLOOKUP($Y$2,Prices!$E$3:$F$17,2,FALSE)*Urban!Y14)+(VLOOKUP($Z$2,Prices!$E$3:$F$17,2,FALSE)*Urban!Z14)+(VLOOKUP($AA$2,Prices!$E$3:$F$17,2,FALSE)*Urban!AA14)+(VLOOKUP($AB$2,Prices!$E$3:$F$17,2,FALSE)*Urban!AB14)+M14 -> 28200000 | AD14: 9865800 | AF14: =AD14-AE14 -> 9865800 | AH14: =AD14+AG14 -> 9865800 | AI14: =AH14/M14 -> 0.34985106 | AJ14: =AH14/AC14 -> 0.34985106
A15: 13 | I15: IYA OPE | J15: SWR | K15: Agege | L15: CTAH0017 | M15: =IFERROR(VLOOKUP($L15,[1]Consolidated!$C$9:$AC$341,27,0),0) -> 18800000 | N15: =IFERROR(VLOOKUP($L15,[1]Consolidated!$C$9:$AC$341,5,0),0) -> 80 | AC15: =(VLOOKUP($O$2,Prices!$E$3:$F$17,2,FALSE)*Urban!O15)+(VLOOKUP($P$2,Prices!$E$3:$F$17,2,FALSE)*Urban!P15)+(VLOOKUP($Q$2,Prices!$E$3:$F$17,2,FALSE)*Urban!Q15)+(VLOOKUP($R$2,Prices!$E$3:$F$17,2,FALSE)*Urban!R15)+(VLOOKUP($S$2,Prices!$E$3:$F$17,2,FALSE)*Urban!S15)+(VLOOKUP($T$2,Prices!$E$3:$F$17,2,FALSE)*Urban!T15)+(VLOOKUP($U$2,Prices!$E$3:$F$17,2,FALSE)*Urban!U15)+(VLOOKUP($V$2,Prices!$E$3:$F$17,2,FALSE)*Urban!V15)+(VLOOKUP($W$2,Prices!$E$3:$F$17,2,FALSE)*Urban!W15)+(VLOOKUP($X$2,Prices!$E$3:$F$17,2,FALSE)*Urban!X15)+(VLOOKUP($Y$2,Prices!$E$3:$F$17,2,FALSE)*Urban!Y15)+(VLOOKUP($Z$2,Prices!$E$3:$F$17,2,FALSE)*Urban!Z15)+(VLOOKUP($AA$2,Prices!$E$3:$F$17,2,FALSE)*Urban!AA15)+(VLOOKUP($AB$2,Prices!$E$3:$F$17,2,FALSE)*Urban!AB15)+M15 -> 18800000 | AD15: 0 | AF15: =AD15-AE15 -> 0 | AH15: =AD15+AG15 -> 0 | AI15: =AH15/M15 -> 0 | AJ15: =AH15/AC15 -> 0
A16: 14 | I16: KEMI SOLOLA | J16: SWR | K16: Agege | L16: CTAH0003 | M16: =IFERROR(VLOOKUP($L16,'[2]Top WH -National'!$D$9:$AC$124,26,0),0) -> 274042000 | N16: =IFERROR(VLOOKUP($L16,'[2]Top WH -National'!$D$9:$AC$124,4,0),0) -> 1331 | AC16: =(VLOOKUP($O$2,Prices!$E$3:$F$17,2,FALSE)*Urban!O16)+(VLOOKUP($P$2,Prices!$E$3:$F$17,2,FALSE)*Urban!P16)+(VLOOKUP($Q$2,Prices!$E$3:$F$17,2,FALSE)*Urban!Q16)+(VLOOKUP($R$2,Prices!$E$3:$F$17,2,FALSE)*Urban!R16)+(VLOOKUP($S$2,Prices!$E$3:$F$17,2,FALSE)*Urban!S16)+(VLOOKUP($T$2,Prices!$E$3:$F$17,2,FALSE)*Urban!T16)+(VLOOKUP($U$2,Prices!$E$3:$F$17,2,FALSE)*Urban!U16)+(VLOOKUP($V$2,Prices!$E$3:$F$17,2,FALSE)*Urban!V16)+(VLOOKUP($W$2,Prices!$E$3:$F$17,2,FALSE)*Urban!W16)+(VLOOKUP($X$2,Prices!$E$3:$F$17,2,FALSE)*Urban!X16)+(VLOOKUP($Y$2,Prices!$E$3:$F$17,2,FALSE)*Urban!Y16)+(VLOOKUP($Z$2,Prices!$E$3:$F$17,2,FALSE)*Urban!Z16)+(VLOOKUP($AA$2,Prices!$E$3:$F$17,2,FALSE)*Urban!AA16)+(VLOOKUP($AB$2,Prices!$E$3:$F$17,2,FALSE)*Urban!AB16)+M16 -> 274042000 | AD16: 173420000 | AF16: =AD16-AE16 -> 173420000 | AH16: =AD16+AG16 -> 173420000 | AI16: =AH16/M16 -> 0.63282271 | AJ16: =AH16/AC16 -> 0.63282271
A17: 15 | I17: Solid Ventures | J17: SWR | K17: Agege | L17: LAC3860 | M17: =IFERROR(VLOOKUP($L17,[1]Consolidated!$C$9:$AC$341,27,0),0) -> 28930000 | N17: =IFERROR(VLOOKUP($L17,[1]Consolidated!$C$9:$AC$341,5,0),0) -> 120 | AC17: =(VLOOKUP($O$2,Prices!$E$3:$F$17,2,FALSE)*Urban!O17)+(VLOOKUP($P$2,Prices!$E$3:$F$17,2,FALSE)*Urban!P17)+(VLOOKUP($Q$2,Prices!$E$3:$F$17,2,FALSE)*Urban!Q17)+(VLOOKUP($R$2,Prices!$E$3:$F$17,2,FALSE)*Urban!R17)+(VLOOKUP($S$2,Prices!$E$3:$F$17,2,FALSE)*Urban!S17)+(VLOOKUP($T$2,Prices!$E$3:$F$17,2,FALSE)*Urban!T17)+(VLOOKUP($U$2,Prices!$E$3:$F$17,2,FALSE)*Urban!U17)+(VLOOKUP($V$2,Prices!$E$3:$F$17,2,FALSE)*Urban!V17)+(VLOOKUP($W$2,Prices!$E$3:$F$17,2,FALSE)*Urban!W17)+(VLOOKUP($X$2,Prices!$E$3:$F$17,2,FALSE)*Urban!X17)+(VLOOKUP($Y$2,Prices!$E$3:$F$17,2,FALSE)*Urban!Y17)+(VLOOKUP($Z$2,Prices!$E$3:$F$17,2,FALSE)*Urban!Z17)+(VLOOKUP($AA$2,Prices!$E$3:$F$17,2,FALSE)*Urban!AA17)+(VLOOKUP($AB$2,Prices!$E$3:$F$17,2,FALSE)*Urban!AB17)+M17 -> 28930000 | AD17: 10100700 | AF17: =AD17-AE17 -> 10100700 | AH17: =AD17+AG17 -> 10100700 | AI17: =AH17/M17 -> 0.34914276 | AJ17: =AH17/AC17 -> 0.34914276
A18: 16 | I18: Holy water Universal | J18: SWR | K18: Agege | L18: LAC3675 | M18: =IFERROR(VLOOKUP($L18,[1]Consolidated!$C$9:$AC$341,27,0),0) -> 18800000 | N18: =IFERROR(VLOOKUP($L18,[1]Consolidated!$C$9:$AC$341,5,0),0) -> 80 | AC18: =(VLOOKUP($O$2,Prices!$E$3:$F$17,2,FALSE)*Urban!O18)+(VLOOKUP($P$2,Prices!$E$3:$F$17,2,FALSE)*Urban!P18)+(VLOOKUP($Q$2,Prices!$E$3:$F$17,2,FALSE)*Urban!Q18)+(VLOOKUP($R$2,Prices!$E$3:$F$17,2,FALSE)*Urban!R18)+(VLOOKUP($S$2,Prices!$E$3:$F$17,2,FALSE)*Urban!S18)+(VLOOKUP($T$2,Prices!$E$3:$F$17,2,FALSE)*Urban!T18)+(VLOOKUP($U$2,Prices!$E$3:$F$17,2,FALSE)*Urban!U18)+(VLOOKUP($V$2,Prices!$E$3:$F$17,2,FALSE)*Urban!V18)+(VLOOKUP($W$2,Prices!$E$3:$F$17,2,FALSE)*Urban!W18)+(VLOOKUP($X$2,Prices!$E$3:$F$17,2,FALSE)*Urban!X18)+(VLOOKUP($Y$2,Prices!$E$3:$F$17,2,FALSE)*Urban!Y18)+(VLOOKUP($Z$2,Prices!$E$3:$F$17,2,FALSE)*Urban!Z18)+(VLOOKUP($AA$2,Prices!$E$3:$F$17,2,FALSE)*Urban!AA18)+(VLOOKUP($AB$2,Prices!$E$3:$F$17,2,FALSE)*Urban!AB18)+M18 -> 18800000 | AD18: 6577200 | AF18: =AD18-AE18 -> 6577200 | AH18: =AD18+AG18 -> 6577200 | AI18: =AH18/M18 -> 0.34985106 | AJ18: =AH18/AC18 -> 0.34985106
A19: 17 | I19: Modester Ube | J19: SWR | K19: Akure | L19: SWC2850 | M19: =IFERROR(VLOOKUP($L19,[1]Consolidated!$C$9:$AC$341,27,0),0) -> 0 | N19: =IFERROR(VLOOKUP($L19,[1]Consolidated!$C$9:$AC$341,5,0),0) -> 0 | AC19: =(VLOOKUP($O$2,Prices!$E$3:$F$17,2,FALSE)*Urban!O19)+(VLOOKUP($P$2,Prices!$E$3:$F$17,2,FALSE)*Urban!P19)+(VLOOKUP($Q$2,Prices!$E$3:$F$17,2,FALSE)*Urban!Q19)+(VLOOKUP($R$2,Prices!$E$3:$F$17,2,FALSE)*Urban!R19)+(VLOOKUP($S$2,Prices!$E$3:$F$17,2,FALSE)*Urban!S19)+(VLOOKUP($T$2,Prices!$E$3:$F$17,2,FALSE)*Urban!T19)+(VLOOKUP($U$2,Prices!$E$3:$F$17,2,FALSE)*Urban!U19)+(VLOOKUP($V$2,Prices!$E$3:$F$17,2,FALSE)*Urban!V19)+(VLOOKUP($W$2,Prices!$E$3:$F$17,2,FALSE)*Urban!W19)+(VLOOKUP($X$2,Prices!$E$3:$F$17,2,FALSE)*Urban!X19)+(VLOOKUP($Y$2,Prices!$E$3:$F$17,2,FALSE)*Urban!Y19)+(VLOOKUP($Z$2,Prices!$E$3:$F$17,2,FALSE)*Urban!Z19)+(VLOOKUP($AA$2,Prices!$E$3:$F$17,2,FALSE)*Urban!AA19)+(VLOOKUP($AB$2,Prices!$E$3:$F$17,2,FALSE)*Urban!AB19)+M19 -> 0 | AD19: 0 | AF19: =AD19-AE19 -> 0 | AH19: =AD19+AG19 -> 0 | AI19: =AH19/M19 -> #DIV/0! | AJ19: =AH19/AC19 -> #DIV/0!
A20: 18 | I20: Okafor Iloke | J20: SWR | K20: Akure | L20: SWC2335 | M20: =IFERROR(VLOOKUP($L20,[1]Consolidated!$C$9:$AC$341,27,0),0) -> 45120000 | N20: =IFERROR(VLOOKUP($L20,[1]Consolidated!$C$9:$AC$341,5,0),0) -> 180 | AC20: =(VLOOKUP($O$2,Prices!$E$3:$F$17,2,FALSE)*Urban!O20)+(VLOOKUP($P$2,Prices!$E$3:$F$17,2,FALSE)*Urban!P20)+(VLOOKUP($Q$2,Prices!$E$3:$F$17,2,FALSE)*Urban!Q20)+(VLOOKUP($R$2,Prices!$E$3:$F$17,2,FALSE)*Urban!R20)+(VLOOKUP($S$2,Prices!$E$3:$F$17,2,FALSE)*Urban!S20)+(VLOOKUP($T$2,Prices!$E$3:$F$17,2,FALSE)*Urban!T20)+(VLOOKUP($U$2,Prices!$E$3:$F$17,2,FALSE)*Urban!U20)+(VLOOKUP($V$2,Prices!$E$3:$F$17,2,FALSE)*Urban!V20)+(VLOOKUP($W$2,Prices!$E$3:$F$17,2,FALSE)*Urban!W20)+(VLOOKUP($X$2,Prices!$E$3:$F$17,2,FALSE)*Urban!X20)+(VLOOKUP($Y$2,Prices!$E$3:$F$17,2,FALSE)*Urban!Y20)+(VLOOKUP($Z$2,Prices!$E$3:$F$17,2,FALSE)*Urban!Z20)+(VLOOKUP($AA$2,Prices!$E$3:$F$17,2,FALSE)*Urban!AA20)+(VLOOKUP($AB$2,Prices!$E$3:$F$17,2,FALSE)*Urban!AB20)+M20 -> 45120000 | AD20: 14616000 | AF20: =AD20-AE20 -> 14616000 | AH20: =AD20+AG20 -> 14616000 | AI20: =AH20/M20 -> 0.32393617 | AJ20: =AH20/AC20 -> 0.32393617
A21: 19 | I21: St.Judes Stores | J21: SWR | K21: Akure | L21: WCFA000223 | M21: =IFERROR(VLOOKUP($L21,'[2]Top WH -National'!$D$9:$AC$124,26,0),0) -> 71364000 | N21: =IFERROR(VLOOKUP($L21,'[2]Top WH -National'!$D$9:$AC$124,4,0),0) -> 300 | AC21: =(VLOOKUP($O$2,Prices!$E$3:$F$17,2,FALSE)*Urban!O21)+(VLOOKUP($P$2,Prices!$E$3:$F$17,2,FALSE)*Urban!P21)+(VLOOKUP($Q$2,Prices!$E$3:$F$17,2,FALSE)*Urban!Q21)+(VLOOKUP($R$2,Prices!$E$3:$F$17,2,FALSE)*Urban!R21)+(VLOOKUP($S$2,Prices!$E$3:$F$17,2,FALSE)*Urban!S21)+(VLOOKUP($T$2,Prices!$E$3:$F$17,2,FALSE)*Urban!T21)+(VLOOKUP($U$2,Prices!$E$3:$F$17,2,FALSE)*Urban!U21)+(VLOOKUP($V$2,Prices!$E$3:$F$17,2,FALSE)*Urban!V21)+(VLOOKUP($W$2,Prices!$E$3:$F$17,2,FALSE)*Urban!W21)+(VLOOKUP($X$2,Prices!$E$3:$F$17,2,FALSE)*Urban!X21)+(VLOOKUP($Y$2,Prices!$E$3:$F$17,2,FALSE)*Urban!Y21)+(VLOOKUP($Z$2,Prices!$E$3:$F$17,2,FALSE)*Urban!Z21)+(VLOOKUP($AA$2,Prices!$E$3:$F$17,2,FALSE)*Urban!AA21)+(VLOOKUP($AB$2,Prices!$E$3:$F$17,2,FALSE)*Urban!AB21)+M21 -> 71364000 | AD21: 42543000 | AF21: =AD21-AE21 -> 42543000 | AH21: =AD21+AG21 -> 42543000 | AI21: =AH21/M21 -> 0.59614091 | AJ21: =AH21/AC21 -> 0.59614091
A22: 20 | I22: Mc Igwe | J22: SWR | K22: Akure | L22: WCFA000220 | M22: =IFERROR(VLOOKUP($L22,'[2]Top WH -National'!$D$9:$AC$124,26,0),0) -> 69891000 | N22: =IFERROR(VLOOKUP($L22,'[2]Top WH -National'!$D$9:$AC$124,4,0),0) -> 300 | AC22: =(VLOOKUP($O$2,Prices!$E$3:$F$17,2,FALSE)*Urban!O22)+(VLOOKUP($P$2,Prices!$E$3:$F$17,2,FALSE)*Urban!P22)+(VLOOKUP($Q$2,Prices!$E$3:$F$17,2,FALSE)*Urban!Q22)+(VLOOKUP($R$2,Prices!$E$3:$F$17,2,FALSE)*Urban!R22)+(VLOOKUP($S$2,Prices!$E$3:$F$17,2,FALSE)*Urban!S22)+(VLOOKUP($T$2,Prices!$E$3:$F$17,2,FALSE)*Urban!T22)+(VLOOKUP($U$2,Prices!$E$3:$F$17,2,FALSE)*Urban!U22)+(VLOOKUP($V$2,Prices!$E$3:$F$17,2,FALSE)*Urban!V22)+(VLOOKUP($W$2,Prices!$E$3:$F$17,2,FALSE)*Urban!W22)+(VLOOKUP($X$2,Prices!$E$3:$F$17,2,FALSE)*Urban!X22)+(VLOOKUP($Y$2,Prices!$E$3:$F$17,2,FALSE)*Urban!Y22)+(VLOOKUP($Z$2,Prices!$E$3:$F$17,2,FALSE)*Urban!Z22)+(VLOOKUP($AA$2,Prices!$E$3:$F$17,2,FALSE)*Urban!AA22)+(VLOOKUP($AB$2,Prices!$E$3:$F$17,2,FALSE)*Urban!AB22)+M22 -> 69891000 | AD22: 26100000 | AF22: =AD22-AE22 -> 26100000 | AH22: =AD22+AG22 -> 26100000 | AI22: =AH22/M22 -> 0.37343864 | AJ22: =AH22/AC22 -> 0.37343864
A23: 21 | I23: Kelechi Store | J23: SWR | K23: Akure | L23: WCFA000218 | M23: =IFERROR(VLOOKUP($L23,'[2]Top WH -National'!$D$9:$AC$124,26,0),0) -> 70624000 | N23: =IFERROR(VLOOKUP($L23,'[2]Top WH -National'!$D$9:$AC$124,4,0),0) -> 300 | AC23: =(VLOOKUP($O$2,Prices!$E$3:$F$17,2,FALSE)*Urban!O23)+(VLOOKUP($P$2,Prices!$E$3:$F$17,2,FALSE)*Urban!P23)+(VLOOKUP($Q$2,Prices!$E$3:$F$17,2,FALSE)*Urban!Q23)+(VLOOKUP($R$2,Prices!$E$3:$F$17,2,FALSE)*Urban!R23)+(VLOOKUP($S$2,Prices!$E$3:$F$17,2,FALSE)*Urban!S23)+(VLOOKUP($T$2,Prices!$E$3:$F$17,2,FALSE)*Urban!T23)+(VLOOKUP($U$2,Prices!$E$3:$F$17,2,FALSE)*Urban!U23)+(VLOOKUP($V$2,Prices!$E$3:$F$17,2,FALSE)*Urban!V23)+(VLOOKUP($W$2,Prices!$E$3:$F$17,2,FALSE)*Urban!W23)+(VLOOKUP($X$2,Prices!$E$3:$F$17,2,FALSE)*Urban!X23)+(VLOOKUP($Y$2,Prices!$E$3:$F$17,2,FALSE)*Urban!Y23)+(VLOOKUP($Z$2,Prices!$E$3:$F$17,2,FALSE)*Urban!Z23)+(VLOOKUP($AA$2,Prices!$E$3:$F$17,2,FALSE)*Urban!AA23)+(VLOOKUP($AB$2,Prices!$E$3:$F$17,2,FALSE)*Urban!AB23)+M23 -> 70624000 | AD23: 42282000 | AF23: =AD23-AE23 -> 42282000 | AH23: =AD23+AG23 -> 42282000 | AI23: =AH23/M23 -> 0.59869166 | AJ23: =AH23/AC23 -> 0.59869166
A24: 22 | I24: Alhaja Lateef Ayisat | J24: SWR | K24: Akure | L24: WCFA000208 | M24: =IFERROR(VLOOKUP($L24,'[2]Top WH -National'!$D$9:$AC$124,26,0),0) -> 229375000 | N24: =IFERROR(VLOOKUP($L24,'[2]Top WH -National'!$D$9:$AC$124,4,0),0) -> 1004 | AC24: =(VLOOKUP($O$2,Prices!$E$3:$F$17,2,FALSE)*Urban!O24)+(VLOOKUP($P$2,Prices!$E$3:$F$17,2,FALSE)*Urban!P24)+(VLOOKUP($Q$2,Prices!$E$3:$F$17,2,FALSE)*Urban!Q24)+(VLOOKUP($R$2,Prices!$E$3:$F$17,2,FALSE)*Urban!R24)+(VLOOKUP($S$2,Prices!$E$3:$F$17,2,FALSE)*Urban!S24)+(VLOOKUP($T$2,Prices!$E$3:$F$17,2,FALSE)*Urban!T24)+(VLOOKUP($U$2,Prices!$E$3:$F$17,2,FALSE)*Urban!U24)+(VLOOKUP($V$2,Prices!$E$3:$F$17,2,FALSE)*Urban!V24)+(VLOOKUP($W$2,Prices!$E$3:$F$17,2,FALSE)*Urban!W24)+(VLOOKUP($X$2,Prices!$E$3:$F$17,2,FALSE)*Urban!X24)+(VLOOKUP($Y$2,Prices!$E$3:$F$17,2,FALSE)*Urban!Y24)+(VLOOKUP($Z$2,Prices!$E$3:$F$17,2,FALSE)*Urban!Z24)+(VLOOKUP($AA$2,Prices!$E$3:$F$17,2,FALSE)*Urban!AA24)+(VLOOKUP($AB$2,Prices!$E$3:$F$17,2,FALSE)*Urban!AB24)+M24 -> 229375000 | AD24: 138330000 | AF24: =AD24-AE24 -> 138330000 | AH24: =AD24+AG24 -> 138330000 | AI24: =AH24/M24 -> 0.60307357 | AJ24: =AH24/AC24 -> 0.60307357
A25: 23 | I25: Samuel Ube | J25: SWR | K25: Akure | L25: WCFA000177 | M25: =IFERROR(VLOOKUP($L25,'[2]Top WH -National'!$D$9:$AC$124,26,0),0) -> 72774000 | N25: =IFERROR(VLOOKUP($L25,'[2]Top WH -National'!$D$9:$AC$124,4,0),0) -> 300 | AC25: =(VLOOKUP($O$2,Prices!$E$3:$F$17,2,FALSE)*Urban!O25)+(VLOOKUP($P$2,Prices!$E$3:$F$17,2,FALSE)*Urban!P25)+(VLOOKUP($Q$2,Prices!$E$3:$F$17,2,FALSE)*Urban!Q25)+(VLOOKUP($R$2,Prices!$E$3:$F$17,2,FALSE)*Urban!R25)+(VLOOKUP($S$2,Prices!$E$3:$F$17,2,FALSE)*Urban!S25)+(VLOOKUP($T$2,Prices!$E$3:$F$17,2,FALSE)*Urban!T25)+(VLOOKUP($U$2,Prices!$E$3:$F$17,2,FALSE)*Urban!U25)+(VLOOKUP($V$2,Prices!$E$3:$F$17,2,FALSE)*Urban!V25)+(VLOOKUP($W$2,Prices!$E$3:$F$17,2,FALSE)*Urban!W25)+(VLOOKUP($X$2,Prices!$E$3:$F$17,2,FALSE)*Urban!X25)+(VLOOKUP($Y$2,Prices!$E$3:$F$17,2,FALSE)*Urban!Y25)+(VLOOKUP($Z$2,Prices!$E$3:$F$17,2,FALSE)*Urban!Z25)+(VLOOKUP($AA$2,Prices!$E$3:$F$17,2,FALSE)*Urban!AA25)+(VLOOKUP($AB$2,Prices!$E$3:$F$17,2,FALSE)*Urban!AB25)+M25 -> 72774000 | AD25: 39150000 | AF25: =AD25-AE25 -> 39150000 | AH25: =AD25+AG25 -> 39150000 | AI25: =AH25/M25 -> 0.53796686 | AJ25: =AH25/AC25 -> 0.53796686
A26: 24 | I26: Selfas Merchandise Ent. | J26: SWR | K26: Akure | L26: SWC1390 | M26: =IFERROR(VLOOKUP($L26,[1]Consolidated!$C$9:$AC$341,27,0),0) -> 33620000 | N26: =IFERROR(VLOOKUP($L26,[1]Consolidated!$C$9:$AC$341,5,0),0) -> 130 | AC26: =(VLOOKUP($O$2,Prices!$E$3:$F$17,2,FALSE)*Urban!O26)+(VLOOKUP($P$2,Prices!$E$3:$F$17,2,FALSE)*Urban!P26)+(VLOOKUP($Q$2,Prices!$E$3:$F$17,2,FALSE)*Urban!Q26)+(VLOOKUP($R$2,Prices!$E$3:$F$17,2,FALSE)*Urban!R26)+(VLOOKUP($S$2,Prices!$E$3:$F$17,2,FALSE)*Urban!S26)+(VLOOKUP($T$2,Prices!$E$3:$F$17,2,FALSE)*Urban!T26)+(VLOOKUP($U$2,Prices!$E$3:$F$17,2,FALSE)*Urban!U26)+(VLOOKUP($V$2,Prices!$E$3:$F$17,2,FALSE)*Urban!V26)+(VLOOKUP($W$2,Prices!$E$3:$F$17,2,FALSE)*Urban!W26)+(VLOOKUP($X$2,Prices!$E$3:$F$17,2,FALSE)*Urban!X26)+(VLOOKUP($Y$2,Prices!$E$3:$F$17,2,FALSE)*Urban!Y26)+(VLOOKUP($Z$2,Prices!$E$3:$F$17,2,FALSE)*Urban!Z26)+(VLOOKUP($AA$2,Prices!$E$3:$F$17,2,FALSE)*Urban!AA26)+(VLOOKUP($AB$2,Prices!$E$3:$F$17,2,FALSE)*Urban!AB26)+M26 -> 33620000 | AD26: 0 | AF26: =AD26-AE26 -> 0 | AH26: =AD26+AG26 -> 0 | AI26: =AH26/M26 -> 0 | AJ26: =AH26/AC26 -> 0
A27: 25 | I27: Forza Buffalo Investment | J27: SWR | K27: Akure | L27: SWC3412 | M27: =IFERROR(VLOOKUP($L27,[1]Consolidated!$C$9:$AC$341,27,0),0) -> 0 | N27: =IFERROR(VLOOKUP($L27,[1]Consolidated!$C$9:$AC$341,5,0),0) -> 0 | AC27: =(VLOOKUP($O$2,Prices!$E$3:$F$17,2,FALSE)*Urban!O27)+(VLOOKUP($P$2,Prices!$E$3:$F$17,2,FALSE)*Urban!P27)+(VLOOKUP($Q$2,Prices!$E$3:$F$17,2,FALSE)*Urban!Q27)+(VLOOKUP($R$2,Prices!$E$3:$F$17,2,FALSE)*Urban!R27)+(VLOOKUP($S$2,Prices!$E$3:$F$17,2,FALSE)*Urban!S27)+(VLOOKUP($T$2,Prices!$E$3:$F$17,2,FALSE)*Urban!T27)+(VLOOKUP($U$2,Prices!$E$3:$F$17,2,FALSE)*Urban!U27)+(VLOOKUP($V$2,Prices!$E$3:$F$17,2,FALSE)*Urban!V27)+(VLOOKUP($W$2,Prices!$E$3:$F$17,2,FALSE)*Urban!W27)+(VLOOKUP($X$2,Prices!$E$3:$F$17,2,FALSE)*Urban!X27)+(VLOOKUP($Y$2,Prices!$E$3:$F$17,2,FALSE)*Urban!Y27)+(VLOOKUP($Z$2,Prices!$E$3:$F$17,2,FALSE)*Urban!Z27)+(VLOOKUP($AA$2,Prices!$E$3:$F$17,2,FALSE)*Urban!AA27)+(VLOOKUP($AB$2,Prices!$E$3:$F$17,2,FALSE)*Urban!AB27)+M27 -> 0 | AD27: 0 | AF27: =AD27-AE27 -> 0 | AH27: =AD27+AG27 -> 0 | AI27: =AH27/M27 -> #DIV/0! | AJ27: =AH27/AC27 -> #DIV/0!
A28: 26 | I28: IYA KOKORO | J28: SWR | K28: Festac | L28: LAC3572 | M28: =IFERROR(VLOOKUP($L28,[1]Consolidated!$C$9:$AC$341,27,0),0) -> 16242000 | N28: =IFERROR(VLOOKUP($L28,[1]Consolidated!$C$9:$AC$341,5,0),0) -> 75 | AC28: =(VLOOKUP($O$2,Prices!$E$3:$F$17,2,FALSE)*Urban!O28)+(VLOOKUP($P$2,Prices!$E$3:$F$17,2,FALSE)*Urban!P28)+(VLOOKUP($Q$2,Prices!$E$3:$F$17,2,FALSE)*Urban!Q28)+(VLOOKUP($R$2,Prices!$E$3:$F$17,2,FALSE)*Urban!R28)+(VLOOKUP($S$2,Prices!$E$3:$F$17,2,FALSE)*Urban!S28)+(VLOOKUP($T$2,Prices!$E$3:$F$17,2,FALSE)*Urban!T28)+(VLOOKUP($U$2,Prices!$E$3:$F$17,2,FALSE)*Urban!U28)+(VLOOKUP($V$2,Prices!$E$3:$F$17,2,FALSE)*Urban!V28)+(VLOOKUP($W$2,Prices!$E$3:$F$17,2,FALSE)*Urban!W28)+(VLOOKUP($X$2,Prices!$E$3:$F$17,2,FALSE)*Urban!X28)+(VLOOKUP($Y$2,Prices!$E$3:$F$17,2,FALSE)*Urban!Y28)+(VLOOKUP($Z$2,Prices!$E$3:$F$17,2,FALSE)*Urban!Z28)+(VLOOKUP($AA$2,Prices!$E$3:$F$17,2,FALSE)*Urban!AA28)+(VLOOKUP($AB$2,Prices!$E$3:$F$17,2,FALSE)*Urban!AB28)+M28 -> 16242000 | AD28: 3461000 | AF28: =AD28-AE28 -> 3461000 | AH28: =AD28+AG28 -> 3461000 | AI28: =AH28/M28 -> 0.21308952 | AJ28: =AH28/AC28 -> 0.21308952
A29: 27 | I29: T.H. NIG. Enterprises | J29: SWR | K29: Festac | L29: LAC3519 | M29: =IFERROR(VLOOKUP($L29,[1]Consolidated!$C$9:$AC$341,27,0),0) -> 14424000 | N29: =IFERROR(VLOOKUP($L29,[1]Consolidated!$C$9:$AC$341,5,0),0) -> 70 | AC29: =(VLOOKUP($O$2,Prices!$E$3:$F$17,2,FALSE)*Urban!O29)+(VLOOKUP($P$2,Prices!$E$3:$F$17,2,FALSE)*Urban!P29)+(VLOOKUP($Q$2,Prices!$E$3:$F$17,2,FALSE)*Urban!Q29)+(VLOOKUP($R$2,Prices!$E$3:$F$17,2,FALSE)*Urban!R29)+(VLOOKUP($S$2,Prices!$E$3:$F$17,2,FALSE)*Urban!S29)+(VLOOKUP($T$2,Prices!$E$3:$F$17,2,FALSE)*Urban!T29)+(VLOOKUP($U$2,Prices!$E$3:$F$17,2,FALSE)*Urban!U29)+(VLOOKUP($V$2,Prices!$E$3:$F$17,2,FALSE)*Urban!V29)+(VLOOKUP($W$2,Prices!$E$3:$F$17,2,FALSE)*Urban!W29)+(VLOOKUP($X$2,Prices!$E$3:$F$17,2,FALSE)*Urban!X29)+(VLOOKUP($Y$2,Prices!$E$3:$F$17,2,FALSE)*Urban!Y29)+(VLOOKUP($Z$2,Prices!$E$3:$F$17,2,FALSE)*Urban!Z29)+(VLOOKUP($AA$2,Prices!$E$3:$F$17,2,FALSE)*Urban!AA29)+(VLOOKUP($AB$2,Prices!$E$3:$F$17,2,FALSE)*Urban!AB29)+M29 -> 14424000 | AD29: 0 | AF29: =AD29-AE29 -> 0 | AH29: =AD29+AG29 -> 0 | AI29: =AH29/M29 -> 0 | AJ29: =AH29/AC29 -> 0
A30: 28 | I30: CHUKWU EMERIE Stores Limited | J30: SWR | K30: Festac | L30: LAC3531 | M30: =IFERROR(VLOOKUP($L30,'[2]Top WH -National'!$D$9:$AC$124,26,0),0) -> 61481000 | N30: =IFERROR(VLOOKUP($L30,'[2]Top WH -National'!$D$9:$AC$124,4,0),0) -> 300 | AC30: =(VLOOKUP($O$2,Prices!$E$3:$F$17,2,FALSE)*Urban!O30)+(VLOOKUP($P$2,Prices!$E$3:$F$17,2,FALSE)*Urban!P30)+(VLOOKUP($Q$2,Prices!$E$3:$F$17,2,FALSE)*Urban!Q30)+(VLOOKUP($R$2,Prices!$E$3:$F$17,2,FALSE)*Urban!R30)+(VLOOKUP($S$2,Prices!$E$3:$F$17,2,FALSE)*Urban!S30)+(VLOOKUP($T$2,Prices!$E$3:$F$17,2,FALSE)*Urban!T30)+(VLOOKUP($U$2,Prices!$E$3:$F$17,2,FALSE)*Urban!U30)+(VLOOKUP($V$2,Prices!$E$3:$F$17,2,FALSE)*Urban!V30)+(VLOOKUP($W$2,Prices!$E$3:$F$17,2,FALSE)*Urban!W30)+(VLOOKUP($X$2,Prices!$E$3:$F$17,2,FALSE)*Urban!X30)+(VLOOKUP($Y$2,Prices!$E$3:$F$17,2,FALSE)*Urban!Y30)+(VLOOKUP($Z$2,Prices!$E$3:$F$17,2,FALSE)*Urban!Z30)+(VLOOKUP($AA$2,Prices!$E$3:$F$17,2,FALSE)*Urban!AA30)+(VLOOKUP($AB$2,Prices!$E$3:$F$17,2,FALSE)*Urban!AB30)+M30 -> 61481000 | AD30: 37116000 | AF30: =AD30-AE30 -> 37116000 | AH30: =AD30+AG30 -> 37116000 | AI30: =AH30/M30 -> 0.6036987 | AJ30: =AH30/AC30 -> 0.6036987
A31: 29 | G31: =SUM(G3:G30) -> 0 | I31: FLORENCE AGBOOLA | J31: SWR | K31: Festac | L31: LAC3368 | M31: =IFERROR(VLOOKUP($L31,[1]Consolidated!$C$9:$AC$341,27,0),0) -> 14994000 | N31: =IFERROR(VLOOKUP($L31,[1]Consolidated!$C$9:$AC$341,5,0),0) -> 70 | AC31: =(VLOOKUP($O$2,Prices!$E$3:$F$17,2,FALSE)*Urban!O31)+(VLOOKUP($P$2,Prices!$E$3:$F$17,2,FALSE)*Urban!P31)+(VLOOKUP($Q$2,Prices!$E$3:$F$17,2,FALSE)*Urban!Q31)+(VLOOKUP($R$2,Prices!$E$3:$F$17,2,FALSE)*Urban!R31)+(VLOOKUP($S$2,Prices!$E$3:$F$17,2,FALSE)*Urban!S31)+(VLOOKUP($T$2,Prices!$E$3:$F$17,2,FALSE)*Urban!T31)+(VLOOKUP($U$2,Prices!$E$3:$F$17,2,FALSE)*Urban!U31)+(VLOOKUP($V$2,Prices!$E$3:$F$17,2,FALSE)*Urban!V31)+(VLOOKUP($W$2,Prices!$E$3:$F$17,2,FALSE)*Urban!W31)+(VLOOKUP($X$2,Prices!$E$3:$F$17,2,FALSE)*Urban!X31)+(VLOOKUP($Y$2,Prices!$E$3:$F$17,2,FALSE)*Urban!Y31)+(VLOOKUP($Z$2,Prices!$E$3:$F$17,2,FALSE)*Urban!Z31)+(VLOOKUP($AA$2,Prices!$E$3:$F$17,2,FALSE)*Urban!AA31)+(VLOOKUP($AB$2,Prices!$E$3:$F$17,2,FALSE)*Urban!AB31)+M31 -> 14994000 | AD31: 3706000 | AF31: =AD31-AE31 -> 3706000 | AH31: =AD31+AG31 -> 3706000 | AI31: =AH31/M31 -> 0.24716553 | AJ31: =AH31/AC31 -> 0.24716553
A32: 30 | I32: Ibrahim Yahaya | J32: SWR | K32: Festac | L32: LAC2268 | M32: =IFERROR(VLOOKUP($L32,[1]Consolidated!$C$9:$AC$341,27,0),0) -> 31011000 | N32: =IFERROR(VLOOKUP($L32,[1]Consolidated!$C$9:$AC$341,5,0),0) -> 145 | AC32: =(VLOOKUP($O$2,Prices!$E$3:$F$17,2,FALSE)*Urban!O32)+(VLOOKUP($P$2,Prices!$E$3:$F$17,2,FALSE)*Urban!P32)+(VLOOKUP($Q$2,Prices!$E$3:$F$17,2,FALSE)*Urban!Q32)+(VLOOKUP($R$2,Prices!$E$3:$F$17,2,FALSE)*Urban!R32)+(VLOOKUP($S$2,Prices!$E$3:$F$17,2,FALSE)*Urban!S32)+(VLOOKUP($T$2,Prices!$E$3:$F$17,2,FALSE)*Urban!T32)+(VLOOKUP($U$2,Prices!$E$3:$F$17,2,FALSE)*Urban!U32)+(VLOOKUP($V$2,Prices!$E$3:$F$17,2,FALSE)*Urban!V32)+(VLOOKUP($W$2,Prices!$E$3:$F$17,2,FALSE)*Urban!W32)+(VLOOKUP($X$2,Prices!$E$3:$F$17,2,FALSE)*Urban!X32)+(VLOOKUP($Y$2,Prices!$E$3:$F$17,2,FALSE)*Urban!Y32)+(VLOOKUP($Z$2,Prices!$E$3:$F$17,2,FALSE)*Urban!Z32)+(VLOOKUP($AA$2,Prices!$E$3:$F$17,2,FALSE)*Urban!AA32)+(VLOOKUP($AB$2,Prices!$E$3:$F$17,2,FALSE)*Urban!AB32)+M32 -> 31011000 | AD32: 0 | AF32: =AD32-AE32 -> 0 | AH32: =AD32+AG32 -> 0 | AI32: =AH32/M32 -> 0 | AJ32: =AH32/AC32 -> 0
A33: 31 | I33: MOHAMED ALI | J33: SWR | K33: Festac | L33: LAC2259 | M33: =IFERROR(VLOOKUP($L33,[1]Consolidated!$C$9:$AC$341,27,0),0) -> 28831000 | N33: =IFERROR(VLOOKUP($L33,[1]Consolidated!$C$9:$AC$341,5,0),0) -> 135 | AC33: =(VLOOKUP($O$2,Prices!$E$3:$F$17,2,FALSE)*Urban!O33)+(VLOOKUP($P$2,Prices!$E$3:$F$17,2,FALSE)*Urban!P33)+(VLOOKUP($Q$2,Prices!$E$3:$F$17,2,FALSE)*Urban!Q33)+(VLOOKUP($R$2,Prices!$E$3:$F$17,2,FALSE)*Urban!R33)+(VLOOKUP($S$2,Prices!$E$3:$F$17,2,FALSE)*Urban!S33)+(VLOOKUP($T$2,Prices!$E$3:$F$17,2,FALSE)*Urban!T33)+(VLOOKUP($U$2,Prices!$E$3:$F$17,2,FALSE)*Urban!U33)+(VLOOKUP($V$2,Prices!$E$3:$F$17,2,FALSE)*Urban!V33)+(VLOOKUP($W$2,Prices!$E$3:$F$17,2,FALSE)*Urban!W33)+(VLOOKUP($X$2,Prices!$E$3:$F$17,2,FALSE)*Urban!X33)+(VLOOKUP($Y$2,Prices!$E$3:$F$17,2,FALSE)*Urban!Y33)+(VLOOKUP($Z$2,Prices!$E$3:$F$17,2,FALSE)*Urban!Z33)+(VLOOKUP($AA$2,Prices!$E$3:$F$17,2,FALSE)*Urban!AA33)+(VLOOKUP($AB$2,Prices!$E$3:$F$17,2,FALSE)*Urban!AB33)+M33 -> 28831000 | AD33: 6738500 | AF33: =AD33-AE33 -> 6738500 | AH33: =AD33+AG33 -> 6738500 | AI33: =AH33/M33 -> 0.23372412 | AJ33: =AH33/AC33 -> 0.23372412
A34: 32 | I34: IYA AHMED FALY | J34: SWR | K34: Festac | L34: LAC2258 | M34: =IFERROR(VLOOKUP($L34,[1]Consolidated!$C$9:$AC$341,27,0),0) -> 14235000 | N34: =IFERROR(VLOOKUP($L34,[1]Consolidated!$C$9:$AC$341,5,0),0) -> 70 | AC34: =(VLOOKUP($O$2,Prices!$E$3:$F$17,2,FALSE)*Urban!O34)+(VLOOKUP($P$2,Prices!$E$3:$F$17,2,FALSE)*Urban!P34)+(VLOOKUP($Q$2,Prices!$E$3:$F$17,2,FALSE)*Urban!Q34)+(VLOOKUP($R$2,Prices!$E$3:$F$17,2,FALSE)*Urban!R34)+(VLOOKUP($S$2,Prices!$E$3:$F$17,2,FALSE)*Urban!S34)+(VLOOKUP($T$2,Prices!$E$3:$F$17,2,FALSE)*Urban!T34)+(VLOOKUP($U$2,Prices!$E$3:$F$17,2,FALSE)*Urban!U34)+(VLOOKUP($V$2,Prices!$E$3:$F$17,2,FALSE)*Urban!V34)+(VLOOKUP($W$2,Prices!$E$3:$F$17,2,FALSE)*Urban!W34)+(VLOOKUP($X$2,Prices!$E$3:$F$17,2,FALSE)*Urban!X34)+(VLOOKUP($Y$2,Prices!$E$3:$F$17,2,FALSE)*Urban!Y34)+(VLOOKUP($Z$2,Prices!$E$3:$F$17,2,FALSE)*Urban!Z34)+(VLOOKUP($AA$2,Prices!$E$3:$F$17,2,FALSE)*Urban!AA34)+(VLOOKUP($AB$2,Prices!$E$3:$F$17,2,FALSE)*Urban!AB34)+M34 -> 14235000 | AD34: 3691000 | AF34: =AD34-AE34 -> 3691000 | AH34: =AD34+AG34 -> 3691000 | AI34: =AH34/M34 -> 0.25929048 | AJ34: =AH34/AC34 -> 0.25929048
A35: 33 | I35: GEOMAN OKUMA (GM) | J35: SWR | K35: Festac | L35: LAC2254 | M35: =IFERROR(VLOOKUP($L35,[1]Consolidated!$C$9:$AC$341,27,0),0) -> 26559000 | N35: =IFERROR(VLOOKUP($L35,[1]Consolidated!$C$9:$AC$341,5,0),0) -> 130 | AC35: =(VLOOKUP($O$2,Prices!$E$3:$F$17,2,FALSE)*Urban!O35)+(VLOOKUP($P$2,Prices!$E$3:$F$17,2,FALSE)*Urban!P35)+(VLOOKUP($Q$2,Prices!$E$3:$F$17,2,FALSE)*Urban!Q35)+(VLOOKUP($R$2,Prices!$E$3:$F$17,2,FALSE)*Urban!R35)+(VLOOKUP($S$2,Prices!$E$3:$F$17,2,FALSE)*Urban!S35)+(VLOOKUP($T$2,Prices!$E$3:$F$17,2,FALSE)*Urban!T35)+(VLOOKUP($U$2,Prices!$E$3:$F$17,2,FALSE)*Urban!U35)+(VLOOKUP($V$2,Prices!$E$3:$F$17,2,FALSE)*Urban!V35)+(VLOOKUP($W$2,Prices!$E$3:$F$17,2,FALSE)*Urban!W35)+(VLOOKUP($X$2,Prices!$E$3:$F$17,2,FALSE)*Urban!X35)+(VLOOKUP($Y$2,Prices!$E$3:$F$17,2,FALSE)*Urban!Y35)+(VLOOKUP($Z$2,Prices!$E$3:$F$17,2,FALSE)*Urban!Z35)+(VLOOKUP($AA$2,Prices!$E$3:$F$17,2,FALSE)*Urban!AA35)+(VLOOKUP($AB$2,Prices!$E$3:$F$17,2,FALSE)*Urban!AB35)+M35 -> 26559000 | AD35: 6569000 | AF35: =AD35-AE35 -> 6569000 | AH35: =AD35+AG35 -> 6569000 | AI35: =AH35/M35 -> 0.24733612 | AJ35: =AH35/AC35 -> 0.24733612
A36: 34 | I36: EDWIN ONWUAMAIZU | J36: SWR | K36: Festac | L36: LAC2253 | M36: =IFERROR(VLOOKUP($L36,[1]Consolidated!$C$9:$AC$341,27,0),0) -> 27831000 | N36: =IFERROR(VLOOKUP($L36,[1]Consolidated!$C$9:$AC$341,5,0),0) -> 130 | AC36: =(VLOOKUP($O$2,Prices!$E$3:$F$17,2,FALSE)*Urban!O36)+(VLOOKUP($P$2,Prices!$E$3:$F$17,2,FALSE)*Urban!P36)+(VLOOKUP($Q$2,Prices!$E$3:$F$17,2,FALSE)*Urban!Q36)+(VLOOKUP($R$2,Prices!$E$3:$F$17,2,FALSE)*Urban!R36)+(VLOOKUP($S$2,Prices!$E$3:$F$17,2,FALSE)*Urban!S36)+(VLOOKUP($T$2,Prices!$E$3:$F$17,2,FALSE)*Urban!T36)+(VLOOKUP($U$2,Prices!$E$3:$F$17,2,FALSE)*Urban!U36)+(VLOOKUP($V$2,Prices!$E$3:$F$17,2,FALSE)*Urban!V36)+(VLOOKUP($W$2,Prices!$E$3:$F$17,2,FALSE)*Urban!W36)+(VLOOKUP($X$2,Prices!$E$3:$F$17,2,FALSE)*Urban!X36)+(VLOOKUP($Y$2,Prices!$E$3:$F$17,2,FALSE)*Urban!Y36)+(VLOOKUP($Z$2,Prices!$E$3:$F$17,2,FALSE)*Urban!Z36)+(VLOOKUP($AA$2,Prices!$E$3:$F$17,2,FALSE)*Urban!AA36)+(VLOOKUP($AB$2,Prices!$E$3:$F$17,2,FALSE)*Urban!AB36)+M36 -> 27831000 | AD36: 0 | AF36: =AD36-AE36 -> 0 | AH36: =AD36+AG36 -> 0 | AI36: =AH36/M36 -> 0 | AJ36: =AH36/AC36 -> 0
A37: 35 | I37: IYA PETER (MRS AFOLABI) | J37: SWR | K37: Festac | L37: LAC2143 | M37: =IFERROR(VLOOKUP($L37,[1]Consolidated!$C$9:$AC$341,27,0),0) -> 16115000 | N37: =IFERROR(VLOOKUP($L37,[1]Consolidated!$C$9:$AC$341,5,0),0) -> 75 | AC37: =(VLOOKUP($O$2,Prices!$E$3:$F$17,2,FALSE)*Urban!O37)+(VLOOKUP($P$2,Prices!$E$3:$F$17,2,FALSE)*Urban!P37)+(VLOOKUP($Q$2,Prices!$E$3:$F$17,2,FALSE)*Urban!Q37)+(VLOOKUP($R$2,Prices!$E$3:$F$17,2,FALSE)*Urban!R37)+(VLOOKUP($S$2,Prices!$E$3:$F$17,2,FALSE)*Urban!S37)+(VLOOKUP($T$2,Prices!$E$3:$F$17,2,FALSE)*Urban!T37)+(VLOOKUP($U$2,Prices!$E$3:$F$17,2,FALSE)*Urban!U37)+(VLOOKUP($V$2,Prices!$E$3:$F$17,2,FALSE)*Urban!V37)+(VLOOKUP($W$2,Prices!$E$3:$F$17,2,FALSE)*Urban!W37)+(VLOOKUP($X$2,Prices!$E$3:$F$17,2,FALSE)*Urban!X37)+(VLOOKUP($Y$2,Prices!$E$3:$F$17,2,FALSE)*Urban!Y37)+(VLOOKUP($Z$2,Prices!$E$3:$F$17,2,FALSE)*Urban!Z37)+(VLOOKUP($AA$2,Prices!$E$3:$F$17,2,FALSE)*Urban!AA37)+(VLOOKUP($AB$2,Prices!$E$3:$F$17,2,FALSE)*Urban!AB37)+M37 -> 16115000 | AD37: 4383000 | AF37: =AD37-AE37 -> 4383000 | AH37: =AD37+AG37 -> 4383000 | AI37: =AH37/M37 -> 0.27198262 | AJ37: =AH37/AC37 -> 0.27198262
A38: 36 | I38: IYA LATEFATH OLAITAN | J38: SWR | K38: Festac | L38: LAC2255 | M38: =IFERROR(VLOOKUP($L38,[1]Consolidated!$C$9:$AC$341,27,0),0) -> 24909000 | N38: =IFERROR(VLOOKUP($L38,[1]Consolidated!$C$9:$AC$341,5,0),0) -> 120 | AC38: =(VLOOKUP($O$2,Prices!$E$3:$F$17,2,FALSE)*Urban!O38)+(VLOOKUP($P$2,Prices!$E$3:$F$17,2,FALSE)*Urban!P38)+(VLOOKUP($Q$2,Prices!$E$3:$F$17,2,FALSE)*Urban!Q38)+(VLOOKUP($R$2,Prices!$E$3:$F$17,2,FALSE)*Urban!R38)+(VLOOKUP($S$2,Prices!$E$3:$F$17,2,FALSE)*Urban!S38)+(VLOOKUP($T$2,Prices!$E$3:$F$17,2,FALSE)*Urban!T38)+(VLOOKUP($U$2,Prices!$E$3:$F$17,2,FALSE)*Urban!U38)+(VLOOKUP($V$2,Prices!$E$3:$F$17,2,FALSE)*Urban!V38)+(VLOOKUP($W$2,Prices!$E$3:$F$17,2,FALSE)*Urban!W38)+(VLOOKUP($X$2,Prices!$E$3:$F$17,2,FALSE)*Urban!X38)+(VLOOKUP($Y$2,Prices!$E$3:$F$17,2,FALSE)*Urban!Y38)+(VLOOKUP($Z$2,Prices!$E$3:$F$17,2,FALSE)*Urban!Z38)+(VLOOKUP($AA$2,Prices!$E$3:$F$17,2,FALSE)*Urban!AA38)+(VLOOKUP($AB$2,Prices!$E$3:$F$17,2,FALSE)*Urban!AB38)+M38 -> 24909000 | AD38: 6152000 | AF38: =AD38-AE38 -> 6152000 | AH38: =AD38+AG38 -> 6152000 | AI38: =AH38/M38 -> 0.246979 | AJ38: =AH38/AC38 -> 0.246979
A39: 37 | I39: King Joe Incorporation | J39: SWR | K39: Festac | L39: LAC1472 | M39: =IFERROR(VLOOKUP($L39,[1]Consolidated!$C$9:$AC$341,27,0),0) -> 30860000 | N39: =IFERROR(VLOOKUP($L39,[1]Consolidated!$C$9:$AC$341,5,0),0) -> 145 | AC39: =(VLOOKUP($O$2,Prices!$E$3:$F$17,2,FALSE)*Urban!O39)+(VLOOKUP($P$2,Prices!$E$3:$F$17,2,FALSE)*Urban!P39)+(VLOOKUP($Q$2,Prices!$E$3:$F$17,2,FALSE)*Urban!Q39)+(VLOOKUP($R$2,Prices!$E$3:$F$17,2,FALSE)*Urban!R39)+(VLOOKUP($S$2,Prices!$E$3:$F$17,2,FALSE)*Urban!S39)+(VLOOKUP($T$2,Prices!$E$3:$F$17,2,FALSE)*Urban!T39)+(VLOOKUP($U$2,Prices!$E$3:$F$17,2,FALSE)*Urban!U39)+(VLOOKUP($V$2,Prices!$E$3:$F$17,2,FALSE)*Urban!V39)+(VLOOKUP($W$2,Prices!$E$3:$F$17,2,FALSE)*Urban!W39)+(VLOOKUP($X$2,Prices!$E$3:$F$17,2,FALSE)*Urban!X39)+(VLOOKUP($Y$2,Prices!$E$3:$F$17,2,FALSE)*Urban!Y39)+(VLOOKUP($Z$2,Prices!$E$3:$F$17,2,FALSE)*Urban!Z39)+(VLOOKUP($AA$2,Prices!$E$3:$F$17,2,FALSE)*Urban!AA39)+(VLOOKUP($AB$2,Prices!$E$3:$F$17,2,FALSE)*Urban!AB39)+M39 -> 30860000 | AD39: 8228000 | AF39: =AD39-AE39 -> 8228000 | AH39: =AD39+AG39 -> 8228000 | AI39: =AH39/M39 -> 0.26662346 | AJ39: =AH39/AC39 -> 0.26662346
A40: 38 | I40: RASHIDAT OLAJIDE (Fauzat) | J40: SWR | K40: Festac | L40: CTAN0012 | M40: =IFERROR(VLOOKUP($L40,[1]Consolidated!$C$9:$AC$341,27,0),0) -> 26111000 | N40: =IFERROR(VLOOKUP($L40,[1]Consolidated!$C$9:$AC$341,5,0),0) -> 120 | AC40: =(VLOOKUP($O$2,Prices!$E$3:$F$17,2,FALSE)*Urban!O40)+(VLOOKUP($P$2,Prices!$E$3:$F$17,2,FALSE)*Urban!P40)+(VLOOKUP($Q$2,Prices!$E$3:$F$17,2,FALSE)*Urban!Q40)+(VLOOKUP($R$2,Prices!$E$3:$F$17,2,FALSE)*Urban!R40)+(VLOOKUP($S$2,Prices!$E$3:$F$17,2,FALSE)*Urban!S40)+(VLOOKUP($T$2,Prices!$E$3:$F$17,2,FALSE)*Urban!T40)+(VLOOKUP($U$2,Prices!$E$3:$F$17,2,FALSE)*Urban!U40)+(VLOOKUP($V$2,Prices!$E$3:$F$17,2,FALSE)*Urban!V40)+(VLOOKUP($W$2,Prices!$E$3:$F$17,2,FALSE)*Urban!W40)+(VLOOKUP($X$2,Prices!$E$3:$F$17,2,FALSE)*Urban!X40)+(VLOOKUP($Y$2,Prices!$E$3:$F$17,2,FALSE)*Urban!Y40)+(VLOOKUP($Z$2,Prices!$E$3:$F$17,2,FALSE)*Urban!Z40)+(VLOOKUP($AA$2,Prices!$E$3:$F$17,2,FALSE)*Urban!AA40)+(VLOOKUP($AB$2,Prices!$E$3:$F$17,2,FALSE)*Urban!AB40)+M40 -> 26111000 | AD40: 0 | AF40: =AD40-AE40 -> 0 | AH40: =AD40+AG40 -> 0 | AI40: =AH40/M40 -> 0 | AJ40: =AH40/AC40 -> 0
...

Sheet Rural1
A2: S/N | B2: Customer | C2: Area | D2: GBNL URN | E2: Initial Credit Value | F2: To be Utilized | G2: Balance | H2: New Credit Value | I2: Name | J2: Region | K2: AREA | L2: GBNL URN | M2: August '22 Target Value (₦) | N2: Current Target | O2: B & H Switch | P2: Rothmans Switch | Q2: Benson & Hedges Boost | R2: Benson & Hedges Demi-Slims | S2: Benson & Hedges Flavour | T2: Dunhill Switch | U2: ST Moritz By Dunhill | V2: Rothmans Menthol | W2: Pall Mall Filter | X2: Pall Mall Menthol | Y2: Rothmans Flavour | Z2: Royal Std Filter | AA2: Pall Mall - Excel Blend | AB2: Pall Mall Boost | AC2: New August Target Value | AD2: August '22 Initial Credit Deployment (₦) | AE2: August '22 Initial Credit Deployment (₦) BD View | AF2: BD Check | AG2: Extra Credit Request (₦) | AH2: Total Credit for Upload August '22 (₦) | AI2: % Credit Exposure vs Initial Target | AJ2: % Credit Exposure vs New expected volume | AK2: Justification
A3: 1 | I3: EMMANUEL AGRO | J3: SER | K3: Benin | L3: SWC2876 | M3: =IFERROR(VLOOKUP($L3,[3]Consolidated!$C$9:$AC$452,27,0),0) -> 10358900 | N3: =IFERROR(VLOOKUP($L3,[3]Consolidated!$C$9:$AC$452,5,0),0) -> 50 | O3: 0 | S3: 10 | AC3: =(VLOOKUP($O$2,[4]Prices!$E$3:$K$17,2,FALSE)*O3)+(VLOOKUP($P$2,[4]Prices!$J$3:$K$17,2,FALSE)*P3)+(VLOOKUP($Q$2,[4]Prices!$J$3:$K$17,2,FALSE)*Q3)+(VLOOKUP($R$2,[4]Prices!$J$3:$K$17,2,FALSE)*R3)+(VLOOKUP($S$2,[4]Prices!$J$3:$K$17,2,FALSE)*S3)+(VLOOKUP($T$2,[4]Prices!$J$3:$K$17,2,FALSE)*T3)+(VLOOKUP($U$2,[4]Prices!$J$3:$K$17,2,FALSE)*U3)+(VLOOKUP($V$2,[4]Prices!$J$3:$K$17,2,FALSE)*V3)+(VLOOKUP($W$2,[4]Prices!$J$3:$K$17,2,FALSE)*W3)+(VLOOKUP($X$2,[4]Prices!$J$3:$K$17,2,FALSE)*X3)+(VLOOKUP($Y$2,[4]Prices!$J$3:$K$17,2,FALSE)*Y3)+(VLOOKUP($Z$2,[4]Prices!$J$3:$K$17,2,FALSE)*Z3)+(VLOOKUP($AA$2,[4]Prices!$J$3:$K$17,2,FALSE)*AA3)+(VLOOKUP($AB$2,[4]Prices!$J$3:$K$17,2,FALSE)*AB3)+M3 -> 12663900 | AD3: 0 | AF3: =AD3-AE3 -> 0 | AG3: 0 | AH3: =AD3+AG3 -> 0 | AI3: =AH3/M3 -> 0 | AJ3: =AH3/AC3 -> 0
A4: 2 | I4: Benzoro Store | J4: SER | K4: Benin | L4: SWC2755 | M4: =IFERROR(VLOOKUP($L4,[3]Consolidated!$C$9:$AC$452,27,0),0) -> 9468200 | N4: =IFERROR(VLOOKUP($L4,[3]Consolidated!$C$9:$AC$452,5,0),0) -> 50 | AC4: =(VLOOKUP($O$2,[4]Prices!$E$3:$K$17,2,FALSE)*O4)+(VLOOKUP($P$2,[4]Prices!$J$3:$K$17,2,FALSE)*P4)+(VLOOKUP($Q$2,[4]Prices!$J$3:$K$17,2,FALSE)*Q4)+(VLOOKUP($R$2,[4]Prices!$J$3:$K$17,2,FALSE)*R4)+(VLOOKUP($S$2,[4]Prices!$J$3:$K$17,2,FALSE)*S4)+(VLOOKUP($T$2,[4]Prices!$J$3:$K$17,2,FALSE)*T4)+(VLOOKUP($U$2,[4]Prices!$J$3:$K$17,2,FALSE)*U4)+(VLOOKUP($V$2,[4]Prices!$J$3:$K$17,2,FALSE)*V4)+(VLOOKUP($W$2,[4]Prices!$J$3:$K$17,2,FALSE)*W4)+(VLOOKUP($X$2,[4]Prices!$J$3:$K$17,2,FALSE)*X4)+(VLOOKUP($Y$2,[4]Prices!$J$3:$K$17,2,FALSE)*Y4)+(VLOOKUP($Z$2,[4]Prices!$J$3:$K$17,2,FALSE)*Z4)+(VLOOKUP($AA$2,[4]Prices!$J$3:$K$17,2,FALSE)*AA4)+(VLOOKUP($AB$2,[4]Prices!$J$3:$K$17,2,FALSE)*AB4)+M4 -> 9468200 | AF4: =AD4-AE4 -> 0 | AH4: =AD4+AG4 -> 0 | AI4: =AH4/M4 -> 0 | AJ4: =AH4/AC4 -> 0
A5: 3 | I5: Paul Ovieba | J5: SER | K5: Benin | L5: WCFA000159 | M5: =IFERROR(VLOOKUP($L5,[3]Consolidated!$C$9:$AC$452,27,0),0) -> 7420000 | N5: =IFERROR(VLOOKUP($L5,[3]Consolidated!$C$9:$AC$452,5,0),0) -> 40 | AC5: =(VLOOKUP($O$2,[4]Prices!$E$3:$K$17,2,FALSE)*O5)+(VLOOKUP($P$2,[4]Prices!$J$3:$K$17,2,FALSE)*P5)+(VLOOKUP($Q$2,[4]Prices!$J$3:$K$17,2,FALSE)*Q5)+(VLOOKUP($R$2,[4]Prices!$J$3:$K$17,2,FALSE)*R5)+(VLOOKUP($S$2,[4]Prices!$J$3:$K$17,2,FALSE)*S5)+(VLOOKUP($T$2,[4]Prices!$J$3:$K$17,2,FALSE)*T5)+(VLOOKUP($U$2,[4]Prices!$J$3:$K$17,2,FALSE)*U5)+(VLOOKUP($V$2,[4]Prices!$J$3:$K$17,2,FALSE)*V5)+(VLOOKUP($W$2,[4]Prices!$J$3:$K$17,2,FALSE)*W5)+(VLOOKUP($X$2,[4]Prices!$J$3:$K$17,2,FALSE)*X5)+(VLOOKUP($Y$2,[4]Prices!$J$3:$K$17,2,FALSE)*Y5)+(VLOOKUP($Z$2,[4]Prices!$J$3:$K$17,2,FALSE)*Z5)+(VLOOKUP($AA$2,[4]Prices!$J$3:$K$17,2,FALSE)*AA5)+(VLOOKUP($AB$2,[4]Prices!$J$3:$K$17,2,FALSE)*AB5)+M5 -> 7420000 | AF5: =AD5-AE5 -> 0 | AH5: =AD5+AG5 -> 0 | AI5: =AH5/M5 -> 0 | AJ5: =AH5/AC5 -> 0
A6: 4 | I6: Ejike Nnamani (Stockiest) | J6: SER | K6: Benin | L6: SWC0888 | M6: =IFERROR(VLOOKUP($L6,[3]Consolidated!$C$9:$AC$452,27,0),0) -> 5314500 | N6: =IFERROR(VLOOKUP($L6,[3]Consolidated!$C$9:$AC$452,5,0),0) -> 24.95 | AC6: =(VLOOKUP($O$2,[4]Prices!$E$3:$K$17,2,FALSE)*O6)+(VLOOKUP($P$2,[4]Prices!$J$3:$K$17,2,FALSE)*P6)+(VLOOKUP($Q$2,[4]Prices!$J$3:$K$17,2,FALSE)*Q6)+(VLOOKUP($R$2,[4]Prices!$J$3:$K$17,2,FALSE)*R6)+(VLOOKUP($S$2,[4]Prices!$J$3:$K$17,2,FALSE)*S6)+(VLOOKUP($T$2,[4]Prices!$J$3:$K$17,2,FALSE)*T6)+(VLOOKUP($U$2,[4]Prices!$J$3:$K$17,2,FALSE)*U6)+(VLOOKUP($V$2,[4]Prices!$J$3:$K$17,2,FALSE)*V6)+(VLOOKUP($W$2,[4]Prices!$J$3:$K$17,2,FALSE)*W6)+(VLOOKUP($X$2,[4]Prices!$J$3:$K$17,2,FALSE)*X6)+(VLOOKUP($Y$2,[4]Prices!$J$3:$K$17,2,FALSE)*Y6)+(VLOOKUP($Z$2,[4]Prices!$J$3:$K$17,2,FALSE)*Z6)+(VLOOKUP($AA$2,[4]Prices!$J$3:$K$17,2,FALSE)*AA6)+(VLOOKUP($AB$2,[4]Prices!$J$3:$K$17,2,FALSE)*AB6)+M6 -> 5314500 | AF6: =AD6-AE6 -> 0 | AH6: =AD6+AG6 -> 0 | AI6: =AH6/M6 -> 0 | AJ6: =AH6/AC6 -> 0
A7: 5 | I7: Amos Abu | J7: SER | K7: Benin | L7: SWC2356 | M7: =IFERROR(VLOOKUP($L7,[3]Consolidated!$C$9:$AC$452,27,0),0) -> 13223000 | N7: =IFERROR(VLOOKUP($L7,[3]Consolidated!$C$9:$AC$452,5,0),0) -> 70 | AC7: =(VLOOKUP($O$2,[4]Prices!$E$3:$K$17,2,FALSE)*O7)+(VLOOKUP($P$2,[4]Prices!$J$3:$K$17,2,FALSE)*P7)+(VLOOKUP($Q$2,[4]Prices!$J$3:$K$17,2,FALSE)*Q7)+(VLOOKUP($R$2,[4]Prices!$J$3:$K$17,2,FALSE)*R7)+(VLOOKUP($S$2,[4]Prices!$J$3:$K$17,2,FALSE)*S7)+(VLOOKUP($T$2,[4]Prices!$J$3:$K$17,2,FALSE)*T7)+(VLOOKUP($U$2,[4]Prices!$J$3:$K$17,2,FALSE)*U7)+(VLOOKUP($V$2,[4]Prices!$J$3:$K$17,2,FALSE)*V7)+(VLOOKUP($W$2,[4]Prices!$J$3:$K$17,2,FALSE)*W7)+(VLOOKUP($X$2,[4]Prices!$J$3:$K$17,2,FALSE)*X7)+(VLOOKUP($Y$2,[4]Prices!$J$3:$K$17,2,FALSE)*Y7)+(VLOOKUP($Z$2,[4]Prices!$J$3:$K$17,2,FALSE)*Z7)+(VLOOKUP($AA$2,[4]Prices!$J$3:$K$17,2,FALSE)*AA7)+(VLOOKUP($AB$2,[4]Prices!$J$3:$K$17,2,FALSE)*AB7)+M7 -> 13223000 | AF7: =AD7-AE7 -> 0 | AH7: =AD7+AG7 -> 0 | AI7: =AH7/M7 -> 0 | AJ7: =AH7/AC7 -> 0
A8: 6 | I8: Otega Super Store | J8: SER | K8: Benin | L8: SWC2203 | M8: =IFERROR(VLOOKUP($L8,[3]Consolidated!$C$9:$AC$452,27,0),0) -> 6528900 | N8: =IFERROR(VLOOKUP($L8,[3]Consolidated!$C$9:$AC$452,5,0),0) -> 35 | AC8: =(VLOOKUP($O$2,[4]Prices!$E$3:$K$17,2,FALSE)*O8)+(VLOOKUP($P$2,[4]Prices!$J$3:$K$17,2,FALSE)*P8)+(VLOOKUP($Q$2,[4]Prices!$J$3:$K$17,2,FALSE)*Q8)+(VLOOKUP($R$2,[4]Prices!$J$3:$K$17,2,FALSE)*R8)+(VLOOKUP($S$2,[4]Prices!$J$3:$K$17,2,FALSE)*S8)+(VLOOKUP($T$2,[4]Prices!$J$3:$K$17,2,FALSE)*T8)+(VLOOKUP($U$2,[4]Prices!$J$3:$K$17,2,FALSE)*U8)+(VLOOKUP($V$2,[4]Prices!$J$3:$K$17,2,FALSE)*V8)+(VLOOKUP($W$2,[4]Prices!$J$3:$K$17,2,FALSE)*W8)+(VLOOKUP($X$2,[4]Prices!$J$3:$K$17,2,FALSE)*X8)+(VLOOKUP($Y$2,[4]Prices!$J$3:$K$17,2,FALSE)*Y8)+(VLOOKUP($Z$2,[4]Prices!$J$3:$K$17,2,FALSE)*Z8)+(VLOOKUP($AA$2,[4]Prices!$J$3:$K$17,2,FALSE)*AA8)+(VLOOKUP($AB$2,[4]Prices!$J$3:$K$17,2,FALSE)*AB8)+M8 -> 6528900 | AF8: =AD8-AE8 -> 0 | AH8: =AD8+AG8 -> 0 | AI8: =AH8/M8 -> 0 | AJ8: =AH8/AC8 -> 0
A9: 7 | I9: Madam Isaac Chukwudike (RME) | J9: SER | K9: Benin | L9: SWC1818 | M9: =IFERROR(VLOOKUP($L9,[3]Consolidated!$C$9:$AC$452,27,0),0) -> 7289100 | N9: =IFERROR(VLOOKUP($L9,[3]Consolidated!$C$9:$AC$452,5,0),0) -> 35 | AC9: =(VLOOKUP($O$2,[4]Prices!$E$3:$K$17,2,FALSE)*O9)+(VLOOKUP($P$2,[4]Prices!$J$3:$K$17,2,FALSE)*P9)+(VLOOKUP($Q$2,[4]Prices!$J$3:$K$17,2,FALSE)*Q9)+(VLOOKUP($R$2,[4]Prices!$J$3:$K$17,2,FALSE)*R9)+(VLOOKUP($S$2,[4]Prices!$J$3:$K$17,2,FALSE)*S9)+(VLOOKUP($T$2,[4]Prices!$J$3:$K$17,2,FALSE)*T9)+(VLOOKUP($U$2,[4]Prices!$J$3:$K$17,2,FALSE)*U9)+(VLOOKUP($V$2,[4]Prices!$J$3:$K$17,2,FALSE)*V9)+(VLOOKUP($W$2,[4]Prices!$J$3:$K$17,2,FALSE)*W9)+(VLOOKUP($X$2,[4]Prices!$J$3:$K$17,2,FALSE)*X9)+(VLOOKUP($Y$2,[4]Prices!$J$3:$K$17,2,FALSE)*Y9)+(VLOOKUP($Z$2,[4]Prices!$J$3:$K$17,2,FALSE)*Z9)+(VLOOKUP($AA$2,[4]Prices!$J$3:$K$17,2,FALSE)*AA9)+(VLOOKUP($AB$2,[4]Prices!$J$3:$K$17,2,FALSE)*AB9)+M9 -> 7289100 | AF9: =AD9-AE9 -> 0 | AH9: =AD9+AG9 -> 0 | AI9: =AH9/M9 -> 0 | AJ9: =AH9/AC9 -> 0
A10: 8 | I10: Madam Rosemary | J10: SER | K10: Benin | L10: SWC0033 | M10: =IFERROR(VLOOKUP($L10,[3]Consolidated!$C$9:$AC$452,27,0),0) -> 7017150 | N10: =IFERROR(VLOOKUP($L10,[3]Consolidated!$C$9:$AC$452,5,0),0) -> 35 | AC10: =(VLOOKUP($O$2,[4]Prices!$E$3:$K$17,2,FALSE)*O10)+(VLOOKUP($P$2,[4]Prices!$J$3:$K$17,2,FALSE)*P10)+(VLOOKUP($Q$2,[4]Prices!$J$3:$K$17,2,FALSE)*Q10)+(VLOOKUP($R$2,[4]Prices!$J$3:$K$17,2,FALSE)*R10)+(VLOOKUP($S$2,[4]Prices!$J$3:$K$17,2,FALSE)*S10)+(VLOOKUP($T$2,[4]Prices!$J$3:$K$17,2,FALSE)*T10)+(VLOOKUP($U$2,[4]Prices!$J$3:$K$17,2,FALSE)*U10)+(VLOOKUP($V$2,[4]Prices!$J$3:$K$17,2,FALSE)*V10)+(VLOOKUP($W$2,[4]Prices!$J$3:$K$17,2,FALSE)*W10)+(VLOOKUP($X$2,[4]Prices!$J$3:$K$17,2,FALSE)*X10)+(VLOOKUP($Y$2,[4]Prices!$J$3:$K$17,2,FALSE)*Y10)+(VLOOKUP($Z$2,[4]Prices!$J$3:$K$17,2,FALSE)*Z10)+(VLOOKUP($AA$2,[4]Prices!$J$3:$K$17,2,FALSE)*AA10)+(VLOOKUP($AB$2,[4]Prices!$J$3:$K$17,2,FALSE)*AB10)+M10 -> 7017150 | AF10: =AD10-AE10 -> 0 | AH10: =AD10+AG10 -> 0 | AI10: =AH10/M10 -> 0 | AJ10: =AH10/AC10 -> 0
A11: 9 | I11: Mr Pauluns Store (RME) | J11: SER | K11: Benin | L11: SWC1823 | M11: =IFERROR(VLOOKUP($L11,[3]Consolidated!$C$9:$AC$452,27,0),0) -> 0 | N11: =IFERROR(VLOOKUP($L11,[3]Consolidated!$C$9:$AC$452,5,0),0) -> 0 | AC11: =(VLOOKUP($O$2,[4]Prices!$E$3:$K$17,2,FALSE)*O11)+(VLOOKUP($P$2,[4]Prices!$J$3:$K$17,2,FALSE)*P11)+(VLOOKUP($Q$2,[4]Prices!$J$3:$K$17,2,FALSE)*Q11)+(VLOOKUP($R$2,[4]Prices!$J$3:$K$17,2,FALSE)*R11)+(VLOOKUP($S$2,[4]Prices!$J$3:$K$17,2,FALSE)*S11)+(VLOOKUP($T$2,[4]Prices!$J$3:$K$17,2,FALSE)*T11)+(VLOOKUP($U$2,[4]Prices!$J$3:$K$17,2,FALSE)*U11)+(VLOOKUP($V$2,[4]Prices!$J$3:$K$17,2,FALSE)*V11)+(VLOOKUP($W$2,[4]Prices!$J$3:$K$17,2,FALSE)*W11)+(VLOOKUP($X$2,[4]Prices!$J$3:$K$17,2,FALSE)*X11)+(VLOOKUP($Y$2,[4]Prices!$J$3:$K$17,2,FALSE)*Y11)+(VLOOKUP($Z$2,[4]Prices!$J$3:$K$17,2,FALSE)*Z11)+(VLOOKUP($AA$2,[4]Prices!$J$3:$K$17,2,FALSE)*AA11)+(VLOOKUP($AB$2,[4]Prices!$J$3:$K$17,2,FALSE)*AB11)+M11 -> 0 | AF11: =AD11-AE11 -> 0 | AH11: =AD11+AG11 -> 0 | AI11: =AH11/M11 -> #DIV/0! | AJ11: =AH11/AC11 -> #DIV/0!
A12: 10 | I12: Larry Happy | J12: SER | K12: Benin | L12: SWC2271 | M12: =IFERROR(VLOOKUP($L12,[3]Consolidated!$C$9:$AC$452,27,0),0) -> 7123800 | N12: =IFERROR(VLOOKUP($L12,[3]Consolidated!$C$9:$AC$452,5,0),0) -> 35 | AC12: =(VLOOKUP($O$2,[4]Prices!$E$3:$K$17,2,FALSE)*O12)+(VLOOKUP($P$2,[4]Prices!$J$3:$K$17,2,FALSE)*P12)+(VLOOKUP($Q$2,[4]Prices!$J$3:$K$17,2,FALSE)*Q12)+(VLOOKUP($R$2,[4]Prices!$J$3:$K$17,2,FALSE)*R12)+(VLOOKUP($S$2,[4]Prices!$J$3:$K$17,2,FALSE)*S12)+(VLOOKUP($T$2,[4]Prices!$J$3:$K$17,2,FALSE)*T12)+(VLOOKUP($U$2,[4]Prices!$J$3:$K$17,2,FALSE)*U12)+(VLOOKUP($V$2,[4]Prices!$J$3:$K$17,2,FALSE)*V12)+(VLOOKUP($W$2,[4]Prices!$J$3:$K$17,2,FALSE)*W12)+(VLOOKUP($X$2,[4]Prices!$J$3:$K$17,2,FALSE)*X12)+(VLOOKUP($Y$2,[4]Prices!$J$3:$K$17,2,FALSE)*Y12)+(VLOOKUP($Z$2,[4]Prices!$J$3:$K$17,2,FALSE)*Z12)+(VLOOKUP($AA$2,[4]Prices!$J$3:$K$17,2,FALSE)*AA12)+(VLOOKUP($AB$2,[4]Prices!$J$3:$K$17,2,FALSE)*AB12)+M12 -> 7123800 | AF12: =AD12-AE12 -> 0 | AH12: =AD12+AG12 -> 0 | AI12: =AH12/M12 -> 0 | AJ12: =AH12/AC12 -> 0
A13: 11 | I13: Lady Jane Integrated | J13: SER | K13: Benin | L13: SWC2174 | M13: =IFERROR(VLOOKUP($L13,[3]Consolidated!$C$9:$AC$452,27,0),0) -> 6819800 | N13: =IFERROR(VLOOKUP($L13,[3]Consolidated!$C$9:$AC$452,5,0),0) -> 35 | AC13: =(VLOOKUP($O$2,[4]Prices!$E$3:$K$17,2,FALSE)*O13)+(VLOOKUP($P$2,[4]Prices!$J$3:$K$17,2,FALSE)*P13)+(VLOOKUP($Q$2,[4]Prices!$J$3:$K$17,2,FALSE)*Q13)+(VLOOKUP($R$2,[4]Prices!$J$3:$K$17,2,FALSE)*R13)+(VLOOKUP($S$2,[4]Prices!$J$3:$K$17,2,FALSE)*S13)+(VLOOKUP($T$2,[4]Prices!$J$3:$K$17,2,FALSE)*T13)+(VLOOKUP($U$2,[4]Prices!$J$3:$K$17,2,FALSE)*U13)+(VLOOKUP($V$2,[4]Prices!$J$3:$K$17,2,FALSE)*V13)+(VLOOKUP($W$2,[4]Prices!$J$3:$K$17,2,FALSE)*W13)+(VLOOKUP($X$2,[4]Prices!$J$3:$K$17,2,FALSE)*X13)+(VLOOKUP($Y$2,[4]Prices!$J$3:$K$17,2,FALSE)*Y13)+(VLOOKUP($Z$2,[4]Prices!$J$3:$K$17,2,FALSE)*Z13)+(VLOOKUP($AA$2,[4]Prices!$J$3:$K$17,2,FALSE)*AA13)+(VLOOKUP($AB$2,[4]Prices!$J$3:$K$17,2,FALSE)*AB13)+M13 -> 6819800 | AF13: =AD13-AE13 -> 0 | AH13: =AD13+AG13 -> 0 | AI13: =AH13/M13 -> 0 | AJ13: =AH13/AC13 -> 0
A14: 12 | I14: S.K Awe | J14: SER | K14: Benin | L14: WCFA000156 | M14: =IFERROR(VLOOKUP($L14,[3]Consolidated!$C$9:$AC$452,27,0),0) -> 7014800 | N14: =IFERROR(VLOOKUP($L14,[3]Consolidated!$C$9:$AC$452,5,0),0) -> 35 | AC14: =(VLOOKUP($O$2,[4]Prices!$E$3:$K$17,2,FALSE)*O14)+(VLOOKUP($P$2,[4]Prices!$J$3:$K$17,2,FALSE)*P14)+(VLOOKUP($Q$2,[4]Prices!$J$3:$K$17,2,FALSE)*Q14)+(VLOOKUP($R$2,[4]Prices!$J$3:$K$17,2,FALSE)*R14)+(VLOOKUP($S$2,[4]Prices!$J$3:$K$17,2,FALSE)*S14)+(VLOOKUP($T$2,[4]Prices!$J$3:$K$17,2,FALSE)*T14)+(VLOOKUP($U$2,[4]Prices!$J$3:$K$17,2,FALSE)*U14)+(VLOOKUP($V$2,[4]Prices!$J$3:$K$17,2,FALSE)*V14)+(VLOOKUP($W$2,[4]Prices!$J$3:$K$17,2,FALSE)*W14)+(VLOOKUP($X$2,[4]Prices!$J$3:$K$17,2,FALSE)*X14)+(VLOOKUP($Y$2,[4]Prices!$J$3:$K$17,2,FALSE)*Y14)+(VLOOKUP($Z$2,[4]Prices!$J$3:$K$17,2,FALSE)*Z14)+(VLOOKUP($AA$2,[4]Prices!$J$3:$K$17,2,FALSE)*AA14)+(VLOOKUP($AB$2,[4]Prices!$J$3:$K$17,2,FALSE)*AB14)+M14 -> 7014800 | AF14: =AD14-AE14 -> 0 | AH14: =AD14+AG14 -> 0 | AI14: =AH14/M14 -> 0 | AJ14: =AH14/AC14 -> 0
A15: 13 | I15: Sunday Oloyede | J15: SER | K15: Benin | L15: SWC2217 | M15: =IFERROR(VLOOKUP($L15,[3]Consolidated!$C$9:$AC$452,27,0),0) -> 22573600 | N15: =IFERROR(VLOOKUP($L15,[3]Consolidated!$C$9:$AC$452,5,0),0) -> 110 | AC15: =(VLOOKUP($O$2,[4]Prices!$E$3:$K$17,2,FALSE)*O15)+(VLOOKUP($P$2,[4]Prices!$J$3:$K$17,2,FALSE)*P15)+(VLOOKUP($Q$2,[4]Prices!$J$3:$K$17,2,FALSE)*Q15)+(VLOOKUP($R$2,[4]Prices!$J$3:$K$17,2,FALSE)*R15)+(VLOOKUP($S$2,[4]Prices!$J$3:$K$17,2,FALSE)*S15)+(VLOOKUP($T$2,[4]Prices!$J$3:$K$17,2,FALSE)*T15)+(VLOOKUP($U$2,[4]Prices!$J$3:$K$17,2,FALSE)*U15)+(VLOOKUP($V$2,[4]Prices!$J$3:$K$17,2,FALSE)*V15)+(VLOOKUP($W$2,[4]Prices!$J$3:$K$17,2,FALSE)*W15)+(VLOOKUP($X$2,[4]Prices!$J$3:$K$17,2,FALSE)*X15)+(VLOOKUP($Y$2,[4]Prices!$J$3:$K$17,2,FALSE)*Y15)+(VLOOKUP($Z$2,[4]Prices!$J$3:$K$17,2,FALSE)*Z15)+(VLOOKUP($AA$2,[4]Prices!$J$3:$K$17,2,FALSE)*AA15)+(VLOOKUP($AB$2,[4]Prices!$J$3:$K$17,2,FALSE)*AB15)+M15 -> 22573600 | AF15: =AD15-AE15 -> 0 | AH15: =AD15+AG15 -> 0 | AI15: =AH15/M15 -> 0 | AJ15: =AH15/AC15 -> 0
... A30: 28 | I30: Ndukwe Ozoemelam | J30: SER | K30: Calabar | L30: SEC003550 | M30: =IFERROR(VLOOKUP($L30,[3]Consolidated!$C$9:$AC$452,27,0),0) -> 18150000 | N30: =IFERROR(VLOOKUP($L30,[3]Consolidated!$C$9:$AC$452,5,0),0) -> 70 | AC30: =(VLOOKUP($O$2,[4]Prices!$E$3:$K$17,2,FALSE)*O30)+(VLOOKUP($P$2,[4]Prices!$J$3:$K$17,2,FALSE)*P30)+(VLOOKUP($Q$2,[4]Prices!$J$3:$K$17,2,FALSE)*Q30)+(VLOOKUP($R$2,[4]Prices!$J$3:$K$17,2,FALSE)*R30)+(VLOOKUP($S$2,[4]Prices!$J$3:$K$17,2,FALSE)*S30)+(VLOOKUP($T$2,[4]Prices!$J$3:$K$17,2,FALSE)*T30)+(VLOOKUP($U$2,[4]Prices!$J$3:$K$17,2,FALSE)*U30)+(VLOOKUP($V$2,[4]Prices!$J$3:$K$17,2,FALSE)*V30)+(VLOOKUP($W$2,[4]Prices!$J$3:$K$17,2,FALSE)*W30)+(VLOOKUP($X$2,[4]Prices!$J$3:$K$17,2,FALSE)*X30)+(VLOOKUP($Y$2,[4]Prices!$J$3:$K$17,2,FALSE)*Y30)+(VLOOKUP($Z$2,[4]Prices!$J$3:$K$17,2,FALSE)*Z30)+(VLOOKUP($AA$2,[4]Prices!$J$3:$K$17,2,FALSE)*AA30)+(VLOOKUP($AB$2,[4]Prices!$J$3:$K$17,2,FALSE)*AB30)+M30 -> 18150000 | AF30: =AD30-AE30 -> 0 | AH30: =AD30+AG30 -> 0 | AI30: =AH30/M30 -> 0 | AJ30: =AH30/AC30 -> 0
A31: 29 | G31: =SUM(G3:G30) -> 0 | I31: LOVETH George Etukudo | J31: SER | K31: Calabar | L31: SEC003369 | M31: =IFERROR(VLOOKUP($L31,[3]Consolidated!$C$9:$AC$452,27,0),0) -> 22567000 | N31: =IFERROR(VLOOKUP($L31,[3]Consolidated!$C$9:$AC$452,5,0),0) -> 105 | AC31: =(VLOOKUP($O$2,[4]Prices!$E$3:$K$17,2,FALSE)*O31)+(VLOOKUP($P$2,[4]Prices!$J$3:$K$17,2,FALSE)*P31)+(VLOOKUP($Q$2,[4]Prices!$J$3:$K$17,2,FALSE)*Q31)+(VLOOKUP($R$2,[4]Prices!$J$3:$K$17,2,FALSE)*R31)+(VLOOKUP($S$2,[4]Prices!$J$3:$K$17,2,FALSE)*S31)+(VLOOKUP($T$2,[4]Prices!$J$3:$K$17,2,FALSE)*T31)+(VLOOKUP($U$2,[4]Prices!$J$3:$K$17,2,FALSE)*U31)+(VLOOKUP($V$2,[4]Prices!$J$3:$K$17,2,FALSE)*V31)+(VLOOKUP($W$2,[4]Prices!$J$3:$K$17,2,FALSE)*W31)+(VLOOKUP($X$2,[4]Prices!$J$3:$K$17,2,FALSE)*X31)+(VLOOKUP($Y$2,[4]Prices!$J$3:$K$17,2,FALSE)*Y31)+(VLOOKUP($Z$2,[4]Prices!$J$3:$K$17,2,FALSE)*Z31)+(VLOOKUP($AA$2,[4]Prices!$J$3:$K$17,2,FALSE)*AA31)+(VLOOKUP($AB$2,[4]Prices!$J$3:$K$17,2,FALSE)*AB31)+M31 -> 22567000 | AF31: =AD31-AE31 -> 0 | AH31: =AD31+AG31 -> 0 | AI31: =AH31/M31 -> 0 | AJ31: =AH31/AC31 -> 0
